Watching for file changes with StatReloader
Performing system checks...

Exception in thread django-main-thread:
Traceback (most recent call last):
  File "C:\Python311\Lib\threading.py", line 1038, in _bootstrap_inner
    self.run()
  File "C:\Python311\Lib\threading.py", line 975, in run
    self._target(*self._args, **self._kwargs)
  File "C:\Users\james\AppData\Roaming\Python\Python311\site-packages\django\utils\autoreload.py", line 64, in wrapper
    fn(*args, **kwargs)
  File "C:\Users\james\AppData\Roaming\Python\Python311\site-packages\django\core\management\commands\runserver.py", line 133, in inner_run
    self.check(display_num_errors=True)
  File "C:\Users\james\AppData\Roaming\Python\Python311\site-packages\django\core\management\base.py", line 486, in check
    all_issues = checks.run_checks(
                 ^^^^^^^^^^^^^^^^^^
  File "C:\Users\james\AppData\Roaming\Python\Python311\site-packages\django\core\checks\registry.py", line 88, in run_checks
    new_errors = check(app_configs=app_configs, databases=databases)
                 ^^^^^^^^^^^^^^^^^^^^^^^^^^^^^^^^^^^^^^^^^^^^^^^^^^^
  File "C:\Users\james\AppData\Roaming\Python\Python311\site-packages\django\core\checks\urls.py", line 14, in check_url_config
    return check_resolver(resolver)
           ^^^^^^^^^^^^^^^^^^^^^^^^
  File "C:\Users\james\AppData\Roaming\Python\Python311\site-packages\django\core\checks\urls.py", line 24, in check_resolver
    return check_method()
           ^^^^^^^^^^^^^^
  File "C:\Users\james\AppData\Roaming\Python\Python311\site-packages\django\urls\resolvers.py", line 519, in check
    for pattern in self.url_patterns:
                   ^^^^^^^^^^^^^^^^^
  File "C:\Users\james\AppData\Roaming\Python\Python311\site-packages\django\utils\functional.py", line 47, in __get__
    res = instance.__dict__[self.name] = self.func(instance)
                                         ^^^^^^^^^^^^^^^^^^^
  File "C:\Users\james\AppData\Roaming\Python\Python311\site-packages\django\urls\resolvers.py", line 738, in url_patterns
    patterns = getattr(self.urlconf_module, "urlpatterns", self.urlconf_module)
                       ^^^^^^^^^^^^^^^^^^^
  File "C:\Users\james\AppData\Roaming\Python\Python311\site-packages\django\utils\functional.py", line 47, in __get__
    res = instance.__dict__[self.name] = self.func(instance)
                                         ^^^^^^^^^^^^^^^^^^^
  File "C:\Users\james\AppData\Roaming\Python\Python311\site-packages\django\urls\resolvers.py", line 731, in urlconf_module
    return import_module(self.urlconf_name)
           ^^^^^^^^^^^^^^^^^^^^^^^^^^^^^^^^
  File "C:\Python311\Lib\importlib\__init__.py", line 126, in import_module
    return _bootstrap._gcd_import(name[level:], package, level)
           ^^^^^^^^^^^^^^^^^^^^^^^^^^^^^^^^^^^^^^^^^^^^^^^^^^^^
  File "<frozen importlib._bootstrap>", line 1206, in _gcd_import
  File "<frozen importlib._bootstrap>", line 1178, in _find_and_load
  File "<frozen importlib._bootstrap>", line 1149, in _find_and_load_unlocked
  File "<frozen importlib._bootstrap>", line 690, in _load_unlocked
  File "<frozen importlib._bootstrap_external>", line 940, in exec_module
  File "<frozen importlib._bootstrap>", line 241, in _call_with_frames_removed
  File "C:\Users\james\Bootcamp\projects\project-75-emans-wordle\wordle_gato365\wordle_gato365\urls.py", line 42, in <module>
    path('game-history/', user_views.general_game_history, name='game_history'),
                          ^^^^^^^^^^^^^^^^^^^^^^^^^^^^^^^
AttributeError: module 'users.views' has no attribute 'general_game_history'
C:\Users\james\Bootcamp\projects\project-75-emans-wordle\wordle_gato365\users\views.py changed, reloading.
Watching for file changes with StatReloader
Performing system checks...

Exception in thread django-main-thread:
Traceback (most recent call last):
  File "C:\Python311\Lib\threading.py", line 1038, in _bootstrap_inner
    self.run()
  File "C:\Python311\Lib\threading.py", line 975, in run
    self._target(*self._args, **self._kwargs)
  File "C:\Users\james\AppData\Roaming\Python\Python311\site-packages\django\utils\autoreload.py", line 64, in wrapper
    fn(*args, **kwargs)
  File "C:\Users\james\AppData\Roaming\Python\Python311\site-packages\django\core\management\commands\runserver.py", line 133, in inner_run
    self.check(display_num_errors=True)
  File "C:\Users\james\AppData\Roaming\Python\Python311\site-packages\django\core\management\base.py", line 486, in check
    all_issues = checks.run_checks(
                 ^^^^^^^^^^^^^^^^^^
  File "C:\Users\james\AppData\Roaming\Python\Python311\site-packages\django\core\checks\registry.py", line 88, in run_checks
    new_errors = check(app_configs=app_configs, databases=databases)
                 ^^^^^^^^^^^^^^^^^^^^^^^^^^^^^^^^^^^^^^^^^^^^^^^^^^^
  File "C:\Users\james\AppData\Roaming\Python\Python311\site-packages\django\core\checks\urls.py", line 14, in check_url_config
    return check_resolver(resolver)
           ^^^^^^^^^^^^^^^^^^^^^^^^
  File "C:\Users\james\AppData\Roaming\Python\Python311\site-packages\django\core\checks\urls.py", line 24, in check_resolver
    return check_method()
           ^^^^^^^^^^^^^^
  File "C:\Users\james\AppData\Roaming\Python\Python311\site-packages\django\urls\resolvers.py", line 519, in check
    for pattern in self.url_patterns:
                   ^^^^^^^^^^^^^^^^^
  File "C:\Users\james\AppData\Roaming\Python\Python311\site-packages\django\utils\functional.py", line 47, in __get__
    res = instance.__dict__[self.name] = self.func(instance)
                                         ^^^^^^^^^^^^^^^^^^^
  File "C:\Users\james\AppData\Roaming\Python\Python311\site-packages\django\urls\resolvers.py", line 738, in url_patterns
    patterns = getattr(self.urlconf_module, "urlpatterns", self.urlconf_module)
                       ^^^^^^^^^^^^^^^^^^^
  File "C:\Users\james\AppData\Roaming\Python\Python311\site-packages\django\utils\functional.py", line 47, in __get__
    res = instance.__dict__[self.name] = self.func(instance)
                                         ^^^^^^^^^^^^^^^^^^^
  File "C:\Users\james\AppData\Roaming\Python\Python311\site-packages\django\urls\resolvers.py", line 731, in urlconf_module
    return import_module(self.urlconf_name)
           ^^^^^^^^^^^^^^^^^^^^^^^^^^^^^^^^
  File "C:\Python311\Lib\importlib\__init__.py", line 126, in import_module
    return _bootstrap._gcd_import(name[level:], package, level)
           ^^^^^^^^^^^^^^^^^^^^^^^^^^^^^^^^^^^^^^^^^^^^^^^^^^^^
  File "<frozen importlib._bootstrap>", line 1206, in _gcd_import
  File "<frozen importlib._bootstrap>", line 1178, in _find_and_load
  File "<frozen importlib._bootstrap>", line 1149, in _find_and_load_unlocked
  File "<frozen importlib._bootstrap>", line 690, in _load_unlocked
  File "<frozen importlib._bootstrap_external>", line 940, in exec_module
  File "<frozen importlib._bootstrap>", line 241, in _call_with_frames_removed
  File "C:\Users\james\Bootcamp\projects\project-75-emans-wordle\wordle_gato365\wordle_gato365\urls.py", line 42, in <module>
    path('game-history/', user_views.general_game_history, name='game_history'),
                          ^^^^^^^^^^^^^^^^^^^^^^^^^^^^^^^
AttributeError: module 'users.views' has no attribute 'general_game_history'
C:\Users\james\Bootcamp\projects\project-75-emans-wordle\wordle_gato365\wordle_gato365\urls.py changed, reloading.
Watching for file changes with StatReloader
Performing system checks...

System check identified no issues (0 silenced).
September 16, 2024 - 13:11:59
Django version 5.0.6, using settings 'wordle_gato365.settings'
Starting development server at http://127.0.0.1:8000/
Quit the server with CTRL-BREAK.

C:\Users\james\Bootcamp\projects\project-75-emans-wordle\wordle_gato365\wordle_gato365\urls.py changed, reloading.
Watching for file changes with StatReloader
Performing system checks...

Exception in thread django-main-thread:
Traceback (most recent call last):
  File "C:\Python311\Lib\threading.py", line 1038, in _bootstrap_inner
    self.run()
  File "C:\Python311\Lib\threading.py", line 975, in run
    self._target(*self._args, **self._kwargs)
  File "C:\Users\james\AppData\Roaming\Python\Python311\site-packages\django\utils\autoreload.py", line 64, in wrapper
    fn(*args, **kwargs)
  File "C:\Users\james\AppData\Roaming\Python\Python311\site-packages\django\core\management\commands\runserver.py", line 133, in inner_run
    self.check(display_num_errors=True)
  File "C:\Users\james\AppData\Roaming\Python\Python311\site-packages\django\core\management\base.py", line 486, in check
    all_issues = checks.run_checks(
                 ^^^^^^^^^^^^^^^^^^
  File "C:\Users\james\AppData\Roaming\Python\Python311\site-packages\django\core\checks\registry.py", line 88, in run_checks
    new_errors = check(app_configs=app_configs, databases=databases)
                 ^^^^^^^^^^^^^^^^^^^^^^^^^^^^^^^^^^^^^^^^^^^^^^^^^^^
  File "C:\Users\james\AppData\Roaming\Python\Python311\site-packages\django\core\checks\urls.py", line 14, in check_url_config
    return check_resolver(resolver)
           ^^^^^^^^^^^^^^^^^^^^^^^^
  File "C:\Users\james\AppData\Roaming\Python\Python311\site-packages\django\core\checks\urls.py", line 24, in check_resolver
    return check_method()
           ^^^^^^^^^^^^^^
  File "C:\Users\james\AppData\Roaming\Python\Python311\site-packages\django\urls\resolvers.py", line 519, in check
    for pattern in self.url_patterns:
                   ^^^^^^^^^^^^^^^^^
  File "C:\Users\james\AppData\Roaming\Python\Python311\site-packages\django\utils\functional.py", line 47, in __get__
    res = instance.__dict__[self.name] = self.func(instance)
                                         ^^^^^^^^^^^^^^^^^^^
  File "C:\Users\james\AppData\Roaming\Python\Python311\site-packages\django\urls\resolvers.py", line 738, in url_patterns
    patterns = getattr(self.urlconf_module, "urlpatterns", self.urlconf_module)
                       ^^^^^^^^^^^^^^^^^^^
  File "C:\Users\james\AppData\Roaming\Python\Python311\site-packages\django\utils\functional.py", line 47, in __get__
    res = instance.__dict__[self.name] = self.func(instance)
                                         ^^^^^^^^^^^^^^^^^^^
  File "C:\Users\james\AppData\Roaming\Python\Python311\site-packages\django\urls\resolvers.py", line 731, in urlconf_module
    return import_module(self.urlconf_name)
           ^^^^^^^^^^^^^^^^^^^^^^^^^^^^^^^^
  File "C:\Python311\Lib\importlib\__init__.py", line 126, in import_module
    return _bootstrap._gcd_import(name[level:], package, level)
           ^^^^^^^^^^^^^^^^^^^^^^^^^^^^^^^^^^^^^^^^^^^^^^^^^^^^
  File "<frozen importlib._bootstrap>", line 1206, in _gcd_import
  File "<frozen importlib._bootstrap>", line 1178, in _find_and_load
  File "<frozen importlib._bootstrap>", line 1149, in _find_and_load_unlocked
  File "<frozen importlib._bootstrap>", line 690, in _load_unlocked
  File "<frozen importlib._bootstrap_external>", line 940, in exec_module
  File "<frozen importlib._bootstrap>", line 241, in _call_with_frames_removed
  File "C:\Users\james\Bootcamp\projects\project-75-emans-wordle\wordle_gato365\wordle_gato365\urls.py", line 42, in <module>
    path('game-history/', user_views.general_game_history, name='game_history'),
                          ^^^^^^^^^^^^^^^^^^^^^^^^^^^^^^^
AttributeError: module 'users.views' has no attribute 'general_game_history'
C:\Users\james\Bootcamp\projects\project-75-emans-wordle\wordle_gato365\users\views.py changed, reloading.
Watching for file changes with StatReloader
Performing system checks...

System check identified no issues (0 silenced).
September 16, 2024 - 13:12:40
Django version 5.0.6, using settings 'wordle_gato365.settings'
Starting development server at http://127.0.0.1:8000/
Quit the server with CTRL-BREAK.

"GET / HTTP/1.1" 200 3015
Internal Server Error: /game-history/
Traceback (most recent call last):
  File "C:\Users\james\AppData\Roaming\Python\Python311\site-packages\django\core\handlers\exception.py", line 55, in inner
    response = get_response(request)
               ^^^^^^^^^^^^^^^^^^^^^
  File "C:\Users\james\AppData\Roaming\Python\Python311\site-packages\django\core\handlers\base.py", line 197, in _get_response
    response = wrapped_callback(request, *callback_args, **callback_kwargs)
               ^^^^^^^^^^^^^^^^^^^^^^^^^^^^^^^^^^^^^^^^^^^^^^^^^^^^^^^^^^^^
  File "C:\Users\james\AppData\Roaming\Python\Python311\site-packages\django\contrib\auth\decorators.py", line 23, in _wrapper_view
    return view_func(request, *args, **kwargs)
           ^^^^^^^^^^^^^^^^^^^^^^^^^^^^^^^^^^^
  File "C:\Users\james\Bootcamp\projects\project-75-emans-wordle\wordle_gato365\users\views.py", line 103, in general_game_history
    return render(request, 'users/game_history.html')
           ^^^^^^^^^^^^^^^^^^^^^^^^^^^^^^^^^^^^^^^^^^
  File "C:\Users\james\AppData\Roaming\Python\Python311\site-packages\django\shortcuts.py", line 25, in render
    content = loader.render_to_string(template_name, context, request, using=using)
              ^^^^^^^^^^^^^^^^^^^^^^^^^^^^^^^^^^^^^^^^^^^^^^^^^^^^^^^^^^^^^^^^^^^^^
  File "C:\Users\james\AppData\Roaming\Python\Python311\site-packages\django\template\loader.py", line 61, in render_to_string
    template = get_template(template_name, using=using)
               ^^^^^^^^^^^^^^^^^^^^^^^^^^^^^^^^^^^^^^^^
  File "C:\Users\james\AppData\Roaming\Python\Python311\site-packages\django\template\loader.py", line 15, in get_template
    return engine.get_template(template_name)
           ^^^^^^^^^^^^^^^^^^^^^^^^^^^^^^^^^^
  File "C:\Users\james\AppData\Roaming\Python\Python311\site-packages\django\template\backends\django.py", line 33, in get_template
    return Template(self.engine.get_template(template_name), self)
                    ^^^^^^^^^^^^^^^^^^^^^^^^^^^^^^^^^^^^^^^
  File "C:\Users\james\AppData\Roaming\Python\Python311\site-packages\django\template\engine.py", line 177, in get_template
    template, origin = self.find_template(template_name)
                       ^^^^^^^^^^^^^^^^^^^^^^^^^^^^^^^^^
  File "C:\Users\james\AppData\Roaming\Python\Python311\site-packages\django\template\engine.py", line 159, in find_template
    template = loader.get_template(name, skip=skip)
               ^^^^^^^^^^^^^^^^^^^^^^^^^^^^^^^^^^^^
  File "C:\Users\james\AppData\Roaming\Python\Python311\site-packages\django\template\loaders\cached.py", line 57, in get_template
    template = super().get_template(template_name, skip)
               ^^^^^^^^^^^^^^^^^^^^^^^^^^^^^^^^^^^^^^^^^
  File "C:\Users\james\AppData\Roaming\Python\Python311\site-packages\django\template\loaders\base.py", line 28, in get_template
    return Template(
           ^^^^^^^^^
  File "C:\Users\james\AppData\Roaming\Python\Python311\site-packages\django\template\base.py", line 154, in __init__
    self.nodelist = self.compile_nodelist()
                    ^^^^^^^^^^^^^^^^^^^^^^^
  File "C:\Users\james\AppData\Roaming\Python\Python311\site-packages\django\template\base.py", line 196, in compile_nodelist
    return parser.parse()
           ^^^^^^^^^^^^^^
  File "C:\Users\james\AppData\Roaming\Python\Python311\site-packages\django\template\base.py", line 510, in parse
    raise self.error(token, e)
  File "C:\Users\james\AppData\Roaming\Python\Python311\site-packages\django\template\base.py", line 508, in parse
    compiled_result = compile_func(self, token)
                      ^^^^^^^^^^^^^^^^^^^^^^^^^
  File "C:\Users\james\AppData\Roaming\Python\Python311\site-packages\django\template\loader_tags.py", line 295, in do_extends
    nodelist = parser.parse()
               ^^^^^^^^^^^^^^
  File "C:\Users\james\AppData\Roaming\Python\Python311\site-packages\django\template\base.py", line 510, in parse
    raise self.error(token, e)
  File "C:\Users\james\AppData\Roaming\Python\Python311\site-packages\django\template\base.py", line 508, in parse
    compiled_result = compile_func(self, token)
                      ^^^^^^^^^^^^^^^^^^^^^^^^^
  File "C:\Users\james\AppData\Roaming\Python\Python311\site-packages\django\template\loader_tags.py", line 240, in do_block
    parser.invalid_block_tag(endblock, "endblock", acceptable_endblocks)
  File "C:\Users\james\AppData\Roaming\Python\Python311\site-packages\django\template\base.py", line 555, in invalid_block_tag
    raise self.error(
django.template.exceptions.TemplateSyntaxError: Invalid block tag on line 42: 'endblock', expected 'endblock' or 'endblock extra_js'. Did you forget to register or load this tag?
"GET /game-history/ HTTP/1.1" 500 181105
Not Found: /favicon.ico
"GET /favicon.ico HTTP/1.1" 404 4681
Internal Server Error: /game-history/
Traceback (most recent call last):
  File "C:\Users\james\AppData\Roaming\Python\Python311\site-packages\django\core\handlers\exception.py", line 55, in inner
    response = get_response(request)
               ^^^^^^^^^^^^^^^^^^^^^
  File "C:\Users\james\AppData\Roaming\Python\Python311\site-packages\django\core\handlers\base.py", line 197, in _get_response
    response = wrapped_callback(request, *callback_args, **callback_kwargs)
               ^^^^^^^^^^^^^^^^^^^^^^^^^^^^^^^^^^^^^^^^^^^^^^^^^^^^^^^^^^^^
  File "C:\Users\james\AppData\Roaming\Python\Python311\site-packages\django\contrib\auth\decorators.py", line 23, in _wrapper_view
    return view_func(request, *args, **kwargs)
           ^^^^^^^^^^^^^^^^^^^^^^^^^^^^^^^^^^^
  File "C:\Users\james\Bootcamp\projects\project-75-emans-wordle\wordle_gato365\users\views.py", line 103, in general_game_history
    return render(request, 'users/game_history.html')
           ^^^^^^^^^^^^^^^^^^^^^^^^^^^^^^^^^^^^^^^^^^
  File "C:\Users\james\AppData\Roaming\Python\Python311\site-packages\django\shortcuts.py", line 25, in render
    content = loader.render_to_string(template_name, context, request, using=using)
              ^^^^^^^^^^^^^^^^^^^^^^^^^^^^^^^^^^^^^^^^^^^^^^^^^^^^^^^^^^^^^^^^^^^^^
  File "C:\Users\james\AppData\Roaming\Python\Python311\site-packages\django\template\loader.py", line 62, in render_to_string
    return template.render(context, request)
           ^^^^^^^^^^^^^^^^^^^^^^^^^^^^^^^^^
  File "C:\Users\james\AppData\Roaming\Python\Python311\site-packages\django\template\backends\django.py", line 61, in render
    return self.template.render(context)
           ^^^^^^^^^^^^^^^^^^^^^^^^^^^^^
  File "C:\Users\james\AppData\Roaming\Python\Python311\site-packages\django\template\base.py", line 171, in render
    return self._render(context)
           ^^^^^^^^^^^^^^^^^^^^^
  File "C:\Users\james\AppData\Roaming\Python\Python311\site-packages\django\template\base.py", line 163, in _render
    return self.nodelist.render(context)
           ^^^^^^^^^^^^^^^^^^^^^^^^^^^^^
  File "C:\Users\james\AppData\Roaming\Python\Python311\site-packages\django\template\base.py", line 1000, in render
    return SafeString("".join([node.render_annotated(context) for node in self]))
                              ^^^^^^^^^^^^^^^^^^^^^^^^^^^^^^^^^^^^^^^^^^^^^^^^^
  File "C:\Users\james\AppData\Roaming\Python\Python311\site-packages\django\template\base.py", line 1000, in <listcomp>
    return SafeString("".join([node.render_annotated(context) for node in self]))
                               ^^^^^^^^^^^^^^^^^^^^^^^^^^^^^^
  File "C:\Users\james\AppData\Roaming\Python\Python311\site-packages\django\template\base.py", line 961, in render_annotated
    return self.render(context)
           ^^^^^^^^^^^^^^^^^^^^
  File "C:\Users\james\AppData\Roaming\Python\Python311\site-packages\django\template\loader_tags.py", line 159, in render
    return compiled_parent._render(context)
           ^^^^^^^^^^^^^^^^^^^^^^^^^^^^^^^^
  File "C:\Users\james\AppData\Roaming\Python\Python311\site-packages\django\template\base.py", line 163, in _render
    return self.nodelist.render(context)
           ^^^^^^^^^^^^^^^^^^^^^^^^^^^^^
  File "C:\Users\james\AppData\Roaming\Python\Python311\site-packages\django\template\base.py", line 1000, in render
    return SafeString("".join([node.render_annotated(context) for node in self]))
                              ^^^^^^^^^^^^^^^^^^^^^^^^^^^^^^^^^^^^^^^^^^^^^^^^^
  File "C:\Users\james\AppData\Roaming\Python\Python311\site-packages\django\template\base.py", line 1000, in <listcomp>
    return SafeString("".join([node.render_annotated(context) for node in self]))
                               ^^^^^^^^^^^^^^^^^^^^^^^^^^^^^^
  File "C:\Users\james\AppData\Roaming\Python\Python311\site-packages\django\template\base.py", line 961, in render_annotated
    return self.render(context)
           ^^^^^^^^^^^^^^^^^^^^
  File "C:\Users\james\AppData\Roaming\Python\Python311\site-packages\django\template\defaulttags.py", line 326, in render
    return nodelist.render(context)
           ^^^^^^^^^^^^^^^^^^^^^^^^
  File "C:\Users\james\AppData\Roaming\Python\Python311\site-packages\django\template\base.py", line 1000, in render
    return SafeString("".join([node.render_annotated(context) for node in self]))
                              ^^^^^^^^^^^^^^^^^^^^^^^^^^^^^^^^^^^^^^^^^^^^^^^^^
  File "C:\Users\james\AppData\Roaming\Python\Python311\site-packages\django\template\base.py", line 1000, in <listcomp>
    return SafeString("".join([node.render_annotated(context) for node in self]))
                               ^^^^^^^^^^^^^^^^^^^^^^^^^^^^^^
  File "C:\Users\james\AppData\Roaming\Python\Python311\site-packages\django\template\base.py", line 961, in render_annotated
    return self.render(context)
           ^^^^^^^^^^^^^^^^^^^^
  File "C:\Users\james\AppData\Roaming\Python\Python311\site-packages\django\template\loader_tags.py", line 65, in render
    result = block.nodelist.render(context)
             ^^^^^^^^^^^^^^^^^^^^^^^^^^^^^^
  File "C:\Users\james\AppData\Roaming\Python\Python311\site-packages\django\template\base.py", line 1000, in render
    return SafeString("".join([node.render_annotated(context) for node in self]))
                              ^^^^^^^^^^^^^^^^^^^^^^^^^^^^^^^^^^^^^^^^^^^^^^^^^
  File "C:\Users\james\AppData\Roaming\Python\Python311\site-packages\django\template\base.py", line 1000, in <listcomp>
    return SafeString("".join([node.render_annotated(context) for node in self]))
                               ^^^^^^^^^^^^^^^^^^^^^^^^^^^^^^
  File "C:\Users\james\AppData\Roaming\Python\Python311\site-packages\django\template\base.py", line 961, in render_annotated
    return self.render(context)
           ^^^^^^^^^^^^^^^^^^^^
  File "C:\Users\james\AppData\Roaming\Python\Python311\site-packages\django\template\loader_tags.py", line 199, in render
    template = context.template.engine.select_template(template_name)
               ^^^^^^^^^^^^^^^^^^^^^^^^^^^^^^^^^^^^^^^^^^^^^^^^^^^^^^
  File "C:\Users\james\AppData\Roaming\Python\Python311\site-packages\django\template\engine.py", line 208, in select_template
    return self.get_template(template_name)
           ^^^^^^^^^^^^^^^^^^^^^^^^^^^^^^^^
  File "C:\Users\james\AppData\Roaming\Python\Python311\site-packages\django\template\engine.py", line 177, in get_template
    template, origin = self.find_template(template_name)
                       ^^^^^^^^^^^^^^^^^^^^^^^^^^^^^^^^^
  File "C:\Users\james\AppData\Roaming\Python\Python311\site-packages\django\template\engine.py", line 159, in find_template
    template = loader.get_template(name, skip=skip)
               ^^^^^^^^^^^^^^^^^^^^^^^^^^^^^^^^^^^^
  File "C:\Users\james\AppData\Roaming\Python\Python311\site-packages\django\template\loaders\cached.py", line 57, in get_template
    template = super().get_template(template_name, skip)
               ^^^^^^^^^^^^^^^^^^^^^^^^^^^^^^^^^^^^^^^^^
  File "C:\Users\james\AppData\Roaming\Python\Python311\site-packages\django\template\loaders\base.py", line 28, in get_template
    return Template(
           ^^^^^^^^^
  File "C:\Users\james\AppData\Roaming\Python\Python311\site-packages\django\template\base.py", line 154, in __init__
    self.nodelist = self.compile_nodelist()
                    ^^^^^^^^^^^^^^^^^^^^^^^
  File "C:\Users\james\AppData\Roaming\Python\Python311\site-packages\django\template\base.py", line 196, in compile_nodelist
    return parser.parse()
           ^^^^^^^^^^^^^^
  File "C:\Users\james\AppData\Roaming\Python\Python311\site-packages\django\template\base.py", line 481, in parse
    raise self.error(token, e)
  File "C:\Users\james\AppData\Roaming\Python\Python311\site-packages\django\template\base.py", line 479, in parse
    filter_expression = self.compile_filter(token.contents)
                        ^^^^^^^^^^^^^^^^^^^^^^^^^^^^^^^^^^^
  File "C:\Users\james\AppData\Roaming\Python\Python311\site-packages\django\template\base.py", line 597, in compile_filter
    return FilterExpression(token, self)
           ^^^^^^^^^^^^^^^^^^^^^^^^^^^^^
  File "C:\Users\james\AppData\Roaming\Python\Python311\site-packages\django\template\base.py", line 693, in __init__
    filter_func = parser.find_filter(filter_name)
                  ^^^^^^^^^^^^^^^^^^^^^^^^^^^^^^^
  File "C:\Users\james\AppData\Roaming\Python\Python311\site-packages\django\template\base.py", line 603, in find_filter
    raise TemplateSyntaxError("Invalid filter: '%s'" % filter_name)
django.template.exceptions.TemplateSyntaxError: Invalid filter: 'div'
"GET /game-history/ HTTP/1.1" 500 261224
C:\Users\james\Bootcamp\projects\project-75-emans-wordle\wordle_gato365\users\views.py changed, reloading.
Watching for file changes with StatReloader
Performing system checks...

System check identified no issues (0 silenced).
September 16, 2024 - 13:24:30
Django version 5.0.6, using settings 'wordle_gato365.settings'
Starting development server at http://127.0.0.1:8000/
Quit the server with CTRL-BREAK.

C:\Users\james\Bootcamp\projects\project-75-emans-wordle\wordle_gato365\users\views.py changed, reloading.
Watching for file changes with StatReloader
Performing system checks...

Exception in thread django-main-thread:
Traceback (most recent call last):
  File "C:\Python311\Lib\threading.py", line 1038, in _bootstrap_inner
    self.run()
  File "C:\Python311\Lib\threading.py", line 975, in run
    self._target(*self._args, **self._kwargs)
  File "C:\Users\james\AppData\Roaming\Python\Python311\site-packages\django\utils\autoreload.py", line 64, in wrapper
    fn(*args, **kwargs)
  File "C:\Users\james\AppData\Roaming\Python\Python311\site-packages\django\core\management\commands\runserver.py", line 133, in inner_run
    self.check(display_num_errors=True)
  File "C:\Users\james\AppData\Roaming\Python\Python311\site-packages\django\core\management\base.py", line 486, in check
    all_issues = checks.run_checks(
                 ^^^^^^^^^^^^^^^^^^
  File "C:\Users\james\AppData\Roaming\Python\Python311\site-packages\django\core\checks\registry.py", line 88, in run_checks
    new_errors = check(app_configs=app_configs, databases=databases)
                 ^^^^^^^^^^^^^^^^^^^^^^^^^^^^^^^^^^^^^^^^^^^^^^^^^^^
  File "C:\Users\james\AppData\Roaming\Python\Python311\site-packages\django\core\checks\urls.py", line 42, in check_url_namespaces_unique
    all_namespaces = _load_all_namespaces(resolver)
                     ^^^^^^^^^^^^^^^^^^^^^^^^^^^^^^
  File "C:\Users\james\AppData\Roaming\Python\Python311\site-packages\django\core\checks\urls.py", line 61, in _load_all_namespaces
    url_patterns = getattr(resolver, "url_patterns", [])
                   ^^^^^^^^^^^^^^^^^^^^^^^^^^^^^^^^^^^^^
  File "C:\Users\james\AppData\Roaming\Python\Python311\site-packages\django\utils\functional.py", line 47, in __get__
    res = instance.__dict__[self.name] = self.func(instance)
                                         ^^^^^^^^^^^^^^^^^^^
  File "C:\Users\james\AppData\Roaming\Python\Python311\site-packages\django\urls\resolvers.py", line 738, in url_patterns
    patterns = getattr(self.urlconf_module, "urlpatterns", self.urlconf_module)
                       ^^^^^^^^^^^^^^^^^^^
  File "C:\Users\james\AppData\Roaming\Python\Python311\site-packages\django\utils\functional.py", line 47, in __get__
    res = instance.__dict__[self.name] = self.func(instance)
                                         ^^^^^^^^^^^^^^^^^^^
  File "C:\Users\james\AppData\Roaming\Python\Python311\site-packages\django\urls\resolvers.py", line 731, in urlconf_module
    return import_module(self.urlconf_name)
           ^^^^^^^^^^^^^^^^^^^^^^^^^^^^^^^^
  File "C:\Python311\Lib\importlib\__init__.py", line 126, in import_module
    return _bootstrap._gcd_import(name[level:], package, level)
           ^^^^^^^^^^^^^^^^^^^^^^^^^^^^^^^^^^^^^^^^^^^^^^^^^^^^
  File "<frozen importlib._bootstrap>", line 1206, in _gcd_import
  File "<frozen importlib._bootstrap>", line 1178, in _find_and_load
  File "<frozen importlib._bootstrap>", line 1149, in _find_and_load_unlocked
  File "<frozen importlib._bootstrap>", line 690, in _load_unlocked
  File "<frozen importlib._bootstrap_external>", line 940, in exec_module
  File "<frozen importlib._bootstrap>", line 241, in _call_with_frames_removed
  File "C:\Users\james\Bootcamp\projects\project-75-emans-wordle\wordle_gato365\wordle_gato365\urls.py", line 19, in <module>
    from users import views as user_views
  File "C:\Users\james\Bootcamp\projects\project-75-emans-wordle\wordle_gato365\users\views.py", line 127
    summary = {
IndentationError: unexpected indent
C:\Users\james\Bootcamp\projects\project-75-emans-wordle\wordle_gato365\users\views.py changed, reloading.
Watching for file changes with StatReloader
Performing system checks...

System check identified no issues (0 silenced).
September 16, 2024 - 13:24:38
Django version 5.0.6, using settings 'wordle_gato365.settings'
Starting development server at http://127.0.0.1:8000/
Quit the server with CTRL-BREAK.

C:\Users\james\Bootcamp\projects\project-75-emans-wordle\wordle_gato365\users\views.py changed, reloading.
Watching for file changes with StatReloader
Performing system checks...

Exception in thread django-main-thread:
Traceback (most recent call last):
  File "C:\Python311\Lib\threading.py", line 1038, in _bootstrap_inner
    self.run()
  File "C:\Python311\Lib\threading.py", line 975, in run
    self._target(*self._args, **self._kwargs)
  File "C:\Users\james\AppData\Roaming\Python\Python311\site-packages\django\utils\autoreload.py", line 64, in wrapper
    fn(*args, **kwargs)
  File "C:\Users\james\AppData\Roaming\Python\Python311\site-packages\django\core\management\commands\runserver.py", line 133, in inner_run
    self.check(display_num_errors=True)
  File "C:\Users\james\AppData\Roaming\Python\Python311\site-packages\django\core\management\base.py", line 486, in check
    all_issues = checks.run_checks(
                 ^^^^^^^^^^^^^^^^^^
  File "C:\Users\james\AppData\Roaming\Python\Python311\site-packages\django\core\checks\registry.py", line 88, in run_checks
    new_errors = check(app_configs=app_configs, databases=databases)
                 ^^^^^^^^^^^^^^^^^^^^^^^^^^^^^^^^^^^^^^^^^^^^^^^^^^^
  File "C:\Users\james\AppData\Roaming\Python\Python311\site-packages\django\core\checks\urls.py", line 42, in check_url_namespaces_unique
    all_namespaces = _load_all_namespaces(resolver)
                     ^^^^^^^^^^^^^^^^^^^^^^^^^^^^^^
  File "C:\Users\james\AppData\Roaming\Python\Python311\site-packages\django\core\checks\urls.py", line 61, in _load_all_namespaces
    url_patterns = getattr(resolver, "url_patterns", [])
                   ^^^^^^^^^^^^^^^^^^^^^^^^^^^^^^^^^^^^^
  File "C:\Users\james\AppData\Roaming\Python\Python311\site-packages\django\utils\functional.py", line 47, in __get__
    res = instance.__dict__[self.name] = self.func(instance)
                                         ^^^^^^^^^^^^^^^^^^^
  File "C:\Users\james\AppData\Roaming\Python\Python311\site-packages\django\urls\resolvers.py", line 738, in url_patterns
    patterns = getattr(self.urlconf_module, "urlpatterns", self.urlconf_module)
                       ^^^^^^^^^^^^^^^^^^^
  File "C:\Users\james\AppData\Roaming\Python\Python311\site-packages\django\utils\functional.py", line 47, in __get__
    res = instance.__dict__[self.name] = self.func(instance)
                                         ^^^^^^^^^^^^^^^^^^^
  File "C:\Users\james\AppData\Roaming\Python\Python311\site-packages\django\urls\resolvers.py", line 731, in urlconf_module
    return import_module(self.urlconf_name)
           ^^^^^^^^^^^^^^^^^^^^^^^^^^^^^^^^
  File "C:\Python311\Lib\importlib\__init__.py", line 126, in import_module
    return _bootstrap._gcd_import(name[level:], package, level)
           ^^^^^^^^^^^^^^^^^^^^^^^^^^^^^^^^^^^^^^^^^^^^^^^^^^^^
  File "<frozen importlib._bootstrap>", line 1206, in _gcd_import
  File "<frozen importlib._bootstrap>", line 1178, in _find_and_load
  File "<frozen importlib._bootstrap>", line 1149, in _find_and_load_unlocked
  File "<frozen importlib._bootstrap>", line 690, in _load_unlocked
  File "<frozen importlib._bootstrap_external>", line 940, in exec_module
  File "<frozen importlib._bootstrap>", line 241, in _call_with_frames_removed
  File "C:\Users\james\Bootcamp\projects\project-75-emans-wordle\wordle_gato365\wordle_gato365\urls.py", line 19, in <module>
    from users import views as user_views
  File "C:\Users\james\Bootcamp\projects\project-75-emans-wordle\wordle_gato365\users\views.py", line 137
    return render(request, 'users/summary_of_all_games.html', {'summary': summary})
IndentationError: unexpected indent
C:\Users\james\Bootcamp\projects\project-75-emans-wordle\wordle_gato365\users\views.py changed, reloading.
Watching for file changes with StatReloader
Performing system checks...

Exception in thread django-main-thread:
Traceback (most recent call last):
  File "C:\Python311\Lib\threading.py", line 1038, in _bootstrap_inner
    self.run()
  File "C:\Python311\Lib\threading.py", line 975, in run
    self._target(*self._args, **self._kwargs)
  File "C:\Users\james\AppData\Roaming\Python\Python311\site-packages\django\utils\autoreload.py", line 64, in wrapper
    fn(*args, **kwargs)
  File "C:\Users\james\AppData\Roaming\Python\Python311\site-packages\django\core\management\commands\runserver.py", line 133, in inner_run
    self.check(display_num_errors=True)
  File "C:\Users\james\AppData\Roaming\Python\Python311\site-packages\django\core\management\base.py", line 486, in check
    all_issues = checks.run_checks(
                 ^^^^^^^^^^^^^^^^^^
  File "C:\Users\james\AppData\Roaming\Python\Python311\site-packages\django\core\checks\registry.py", line 88, in run_checks
    new_errors = check(app_configs=app_configs, databases=databases)
                 ^^^^^^^^^^^^^^^^^^^^^^^^^^^^^^^^^^^^^^^^^^^^^^^^^^^
  File "C:\Users\james\AppData\Roaming\Python\Python311\site-packages\django\core\checks\urls.py", line 42, in check_url_namespaces_unique
    all_namespaces = _load_all_namespaces(resolver)
                     ^^^^^^^^^^^^^^^^^^^^^^^^^^^^^^
  File "C:\Users\james\AppData\Roaming\Python\Python311\site-packages\django\core\checks\urls.py", line 61, in _load_all_namespaces
    url_patterns = getattr(resolver, "url_patterns", [])
                   ^^^^^^^^^^^^^^^^^^^^^^^^^^^^^^^^^^^^^
  File "C:\Users\james\AppData\Roaming\Python\Python311\site-packages\django\utils\functional.py", line 47, in __get__
    res = instance.__dict__[self.name] = self.func(instance)
                                         ^^^^^^^^^^^^^^^^^^^
  File "C:\Users\james\AppData\Roaming\Python\Python311\site-packages\django\urls\resolvers.py", line 738, in url_patterns
    patterns = getattr(self.urlconf_module, "urlpatterns", self.urlconf_module)
                       ^^^^^^^^^^^^^^^^^^^
  File "C:\Users\james\AppData\Roaming\Python\Python311\site-packages\django\utils\functional.py", line 47, in __get__
    res = instance.__dict__[self.name] = self.func(instance)
                                         ^^^^^^^^^^^^^^^^^^^
  File "C:\Users\james\AppData\Roaming\Python\Python311\site-packages\django\urls\resolvers.py", line 731, in urlconf_module
    return import_module(self.urlconf_name)
           ^^^^^^^^^^^^^^^^^^^^^^^^^^^^^^^^
  File "C:\Python311\Lib\importlib\__init__.py", line 126, in import_module
    return _bootstrap._gcd_import(name[level:], package, level)
           ^^^^^^^^^^^^^^^^^^^^^^^^^^^^^^^^^^^^^^^^^^^^^^^^^^^^
  File "<frozen importlib._bootstrap>", line 1206, in _gcd_import
  File "<frozen importlib._bootstrap>", line 1178, in _find_and_load
  File "<frozen importlib._bootstrap>", line 1149, in _find_and_load_unlocked
  File "<frozen importlib._bootstrap>", line 690, in _load_unlocked
  File "<frozen importlib._bootstrap_external>", line 940, in exec_module
  File "<frozen importlib._bootstrap>", line 241, in _call_with_frames_removed
  File "C:\Users\james\Bootcamp\projects\project-75-emans-wordle\wordle_gato365\wordle_gato365\urls.py", line 19, in <module>
    from users import views as user_views
  File "C:\Users\james\Bootcamp\projects\project-75-emans-wordle\wordle_gato365\users\views.py", line 126
    win_rate = (summary['games_won'] / summary['total_games']) * 100
    ^
IndentationError: expected an indented block after 'if' statement on line 125
C:\Users\james\Bootcamp\projects\project-75-emans-wordle\wordle_gato365\users\views.py changed, reloading.
Watching for file changes with StatReloader
Performing system checks...

Exception in thread django-main-thread:
Traceback (most recent call last):
  File "C:\Python311\Lib\threading.py", line 1038, in _bootstrap_inner
    self.run()
  File "C:\Python311\Lib\threading.py", line 975, in run
    self._target(*self._args, **self._kwargs)
  File "C:\Users\james\AppData\Roaming\Python\Python311\site-packages\django\utils\autoreload.py", line 64, in wrapper
    fn(*args, **kwargs)
  File "C:\Users\james\AppData\Roaming\Python\Python311\site-packages\django\core\management\commands\runserver.py", line 133, in inner_run
    self.check(display_num_errors=True)
  File "C:\Users\james\AppData\Roaming\Python\Python311\site-packages\django\core\management\base.py", line 486, in check
    all_issues = checks.run_checks(
                 ^^^^^^^^^^^^^^^^^^
  File "C:\Users\james\AppData\Roaming\Python\Python311\site-packages\django\core\checks\registry.py", line 88, in run_checks
    new_errors = check(app_configs=app_configs, databases=databases)
                 ^^^^^^^^^^^^^^^^^^^^^^^^^^^^^^^^^^^^^^^^^^^^^^^^^^^
  File "C:\Users\james\AppData\Roaming\Python\Python311\site-packages\django\core\checks\urls.py", line 42, in check_url_namespaces_unique
    all_namespaces = _load_all_namespaces(resolver)
                     ^^^^^^^^^^^^^^^^^^^^^^^^^^^^^^
  File "C:\Users\james\AppData\Roaming\Python\Python311\site-packages\django\core\checks\urls.py", line 61, in _load_all_namespaces
    url_patterns = getattr(resolver, "url_patterns", [])
                   ^^^^^^^^^^^^^^^^^^^^^^^^^^^^^^^^^^^^^
  File "C:\Users\james\AppData\Roaming\Python\Python311\site-packages\django\utils\functional.py", line 47, in __get__
    res = instance.__dict__[self.name] = self.func(instance)
                                         ^^^^^^^^^^^^^^^^^^^
  File "C:\Users\james\AppData\Roaming\Python\Python311\site-packages\django\urls\resolvers.py", line 738, in url_patterns
    patterns = getattr(self.urlconf_module, "urlpatterns", self.urlconf_module)
                       ^^^^^^^^^^^^^^^^^^^
  File "C:\Users\james\AppData\Roaming\Python\Python311\site-packages\django\utils\functional.py", line 47, in __get__
    res = instance.__dict__[self.name] = self.func(instance)
                                         ^^^^^^^^^^^^^^^^^^^
  File "C:\Users\james\AppData\Roaming\Python\Python311\site-packages\django\urls\resolvers.py", line 731, in urlconf_module
    return import_module(self.urlconf_name)
           ^^^^^^^^^^^^^^^^^^^^^^^^^^^^^^^^
  File "C:\Python311\Lib\importlib\__init__.py", line 126, in import_module
    return _bootstrap._gcd_import(name[level:], package, level)
           ^^^^^^^^^^^^^^^^^^^^^^^^^^^^^^^^^^^^^^^^^^^^^^^^^^^^
  File "<frozen importlib._bootstrap>", line 1206, in _gcd_import
  File "<frozen importlib._bootstrap>", line 1178, in _find_and_load
  File "<frozen importlib._bootstrap>", line 1149, in _find_and_load_unlocked
  File "<frozen importlib._bootstrap>", line 690, in _load_unlocked
  File "<frozen importlib._bootstrap_external>", line 940, in exec_module
  File "<frozen importlib._bootstrap>", line 241, in _call_with_frames_removed
  File "C:\Users\james\Bootcamp\projects\project-75-emans-wordle\wordle_gato365\wordle_gato365\urls.py", line 19, in <module>
    from users import views as user_views
  File "C:\Users\james\Bootcamp\projects\project-75-emans-wordle\wordle_gato365\users\views.py", line 128
    win_rate = 0
    ^
IndentationError: expected an indented block after 'else' statement on line 127
C:\Users\james\Bootcamp\projects\project-75-emans-wordle\wordle_gato365\users\views.py changed, reloading.
Watching for file changes with StatReloader
Performing system checks...

Exception in thread django-main-thread:
Traceback (most recent call last):
  File "C:\Python311\Lib\threading.py", line 1038, in _bootstrap_inner
    self.run()
  File "C:\Python311\Lib\threading.py", line 975, in run
    self._target(*self._args, **self._kwargs)
  File "C:\Users\james\AppData\Roaming\Python\Python311\site-packages\django\utils\autoreload.py", line 64, in wrapper
    fn(*args, **kwargs)
  File "C:\Users\james\AppData\Roaming\Python\Python311\site-packages\django\core\management\commands\runserver.py", line 133, in inner_run
    self.check(display_num_errors=True)
  File "C:\Users\james\AppData\Roaming\Python\Python311\site-packages\django\core\management\base.py", line 486, in check
    all_issues = checks.run_checks(
                 ^^^^^^^^^^^^^^^^^^
  File "C:\Users\james\AppData\Roaming\Python\Python311\site-packages\django\core\checks\registry.py", line 88, in run_checks
    new_errors = check(app_configs=app_configs, databases=databases)
                 ^^^^^^^^^^^^^^^^^^^^^^^^^^^^^^^^^^^^^^^^^^^^^^^^^^^
  File "C:\Users\james\AppData\Roaming\Python\Python311\site-packages\django\core\checks\urls.py", line 42, in check_url_namespaces_unique
    all_namespaces = _load_all_namespaces(resolver)
                     ^^^^^^^^^^^^^^^^^^^^^^^^^^^^^^
  File "C:\Users\james\AppData\Roaming\Python\Python311\site-packages\django\core\checks\urls.py", line 61, in _load_all_namespaces
    url_patterns = getattr(resolver, "url_patterns", [])
                   ^^^^^^^^^^^^^^^^^^^^^^^^^^^^^^^^^^^^^
  File "C:\Users\james\AppData\Roaming\Python\Python311\site-packages\django\utils\functional.py", line 47, in __get__
    res = instance.__dict__[self.name] = self.func(instance)
                                         ^^^^^^^^^^^^^^^^^^^
  File "C:\Users\james\AppData\Roaming\Python\Python311\site-packages\django\urls\resolvers.py", line 738, in url_patterns
    patterns = getattr(self.urlconf_module, "urlpatterns", self.urlconf_module)
                       ^^^^^^^^^^^^^^^^^^^
  File "C:\Users\james\AppData\Roaming\Python\Python311\site-packages\django\utils\functional.py", line 47, in __get__
    res = instance.__dict__[self.name] = self.func(instance)
                                         ^^^^^^^^^^^^^^^^^^^
  File "C:\Users\james\AppData\Roaming\Python\Python311\site-packages\django\urls\resolvers.py", line 731, in urlconf_module
    return import_module(self.urlconf_name)
           ^^^^^^^^^^^^^^^^^^^^^^^^^^^^^^^^
  File "C:\Python311\Lib\importlib\__init__.py", line 126, in import_module
    return _bootstrap._gcd_import(name[level:], package, level)
           ^^^^^^^^^^^^^^^^^^^^^^^^^^^^^^^^^^^^^^^^^^^^^^^^^^^^
  File "<frozen importlib._bootstrap>", line 1206, in _gcd_import
  File "<frozen importlib._bootstrap>", line 1178, in _find_and_load
  File "<frozen importlib._bootstrap>", line 1149, in _find_and_load_unlocked
  File "<frozen importlib._bootstrap>", line 690, in _load_unlocked
  File "<frozen importlib._bootstrap_external>", line 940, in exec_module
  File "<frozen importlib._bootstrap>", line 241, in _call_with_frames_removed
  File "C:\Users\james\Bootcamp\projects\project-75-emans-wordle\wordle_gato365\wordle_gato365\urls.py", line 19, in <module>
    from users import views as user_views
  File "C:\Users\james\Bootcamp\projects\project-75-emans-wordle\wordle_gato365\users\views.py", line 136
    return render(request, 'users/summary_of_all_games.html', {'summary': summary})
IndentationError: unexpected indent
C:\Users\james\Bootcamp\projects\project-75-emans-wordle\wordle_gato365\users\views.py changed, reloading.
Watching for file changes with StatReloader
Performing system checks...

Exception in thread django-main-thread:
Traceback (most recent call last):
  File "C:\Python311\Lib\threading.py", line 1038, in _bootstrap_inner
    self.run()
  File "C:\Python311\Lib\threading.py", line 975, in run
    self._target(*self._args, **self._kwargs)
  File "C:\Users\james\AppData\Roaming\Python\Python311\site-packages\django\utils\autoreload.py", line 64, in wrapper
    fn(*args, **kwargs)
  File "C:\Users\james\AppData\Roaming\Python\Python311\site-packages\django\core\management\commands\runserver.py", line 133, in inner_run
    self.check(display_num_errors=True)
  File "C:\Users\james\AppData\Roaming\Python\Python311\site-packages\django\core\management\base.py", line 486, in check
    all_issues = checks.run_checks(
                 ^^^^^^^^^^^^^^^^^^
  File "C:\Users\james\AppData\Roaming\Python\Python311\site-packages\django\core\checks\registry.py", line 88, in run_checks
    new_errors = check(app_configs=app_configs, databases=databases)
                 ^^^^^^^^^^^^^^^^^^^^^^^^^^^^^^^^^^^^^^^^^^^^^^^^^^^
  File "C:\Users\james\AppData\Roaming\Python\Python311\site-packages\django\core\checks\urls.py", line 42, in check_url_namespaces_unique
    all_namespaces = _load_all_namespaces(resolver)
                     ^^^^^^^^^^^^^^^^^^^^^^^^^^^^^^
  File "C:\Users\james\AppData\Roaming\Python\Python311\site-packages\django\core\checks\urls.py", line 61, in _load_all_namespaces
    url_patterns = getattr(resolver, "url_patterns", [])
                   ^^^^^^^^^^^^^^^^^^^^^^^^^^^^^^^^^^^^^
  File "C:\Users\james\AppData\Roaming\Python\Python311\site-packages\django\utils\functional.py", line 47, in __get__
    res = instance.__dict__[self.name] = self.func(instance)
                                         ^^^^^^^^^^^^^^^^^^^
  File "C:\Users\james\AppData\Roaming\Python\Python311\site-packages\django\urls\resolvers.py", line 738, in url_patterns
    patterns = getattr(self.urlconf_module, "urlpatterns", self.urlconf_module)
                       ^^^^^^^^^^^^^^^^^^^
  File "C:\Users\james\AppData\Roaming\Python\Python311\site-packages\django\utils\functional.py", line 47, in __get__
    res = instance.__dict__[self.name] = self.func(instance)
                                         ^^^^^^^^^^^^^^^^^^^
  File "C:\Users\james\AppData\Roaming\Python\Python311\site-packages\django\urls\resolvers.py", line 731, in urlconf_module
    return import_module(self.urlconf_name)
           ^^^^^^^^^^^^^^^^^^^^^^^^^^^^^^^^
  File "C:\Python311\Lib\importlib\__init__.py", line 126, in import_module
    return _bootstrap._gcd_import(name[level:], package, level)
           ^^^^^^^^^^^^^^^^^^^^^^^^^^^^^^^^^^^^^^^^^^^^^^^^^^^^
  File "<frozen importlib._bootstrap>", line 1206, in _gcd_import
  File "<frozen importlib._bootstrap>", line 1178, in _find_and_load
  File "<frozen importlib._bootstrap>", line 1149, in _find_and_load_unlocked
  File "<frozen importlib._bootstrap>", line 690, in _load_unlocked
  File "<frozen importlib._bootstrap_external>", line 940, in exec_module
  File "<frozen importlib._bootstrap>", line 241, in _call_with_frames_removed
  File "C:\Users\james\Bootcamp\projects\project-75-emans-wordle\wordle_gato365\wordle_gato365\urls.py", line 19, in <module>
    from users import views as user_views
  File "C:\Users\james\Bootcamp\projects\project-75-emans-wordle\wordle_gato365\users\views.py", line 136
    return render(request, 'users/summary_of_all_games.html', {'summary': summary})
IndentationError: unexpected indent
C:\Users\james\Bootcamp\projects\project-75-emans-wordle\wordle_gato365\users\views.py changed, reloading.
Watching for file changes with StatReloader
Performing system checks...

Exception in thread django-main-thread:
Traceback (most recent call last):
  File "C:\Python311\Lib\threading.py", line 1038, in _bootstrap_inner
    self.run()
  File "C:\Python311\Lib\threading.py", line 975, in run
    self._target(*self._args, **self._kwargs)
  File "C:\Users\james\AppData\Roaming\Python\Python311\site-packages\django\utils\autoreload.py", line 64, in wrapper
    fn(*args, **kwargs)
  File "C:\Users\james\AppData\Roaming\Python\Python311\site-packages\django\core\management\commands\runserver.py", line 133, in inner_run
    self.check(display_num_errors=True)
  File "C:\Users\james\AppData\Roaming\Python\Python311\site-packages\django\core\management\base.py", line 486, in check
    all_issues = checks.run_checks(
                 ^^^^^^^^^^^^^^^^^^
  File "C:\Users\james\AppData\Roaming\Python\Python311\site-packages\django\core\checks\registry.py", line 88, in run_checks
    new_errors = check(app_configs=app_configs, databases=databases)
                 ^^^^^^^^^^^^^^^^^^^^^^^^^^^^^^^^^^^^^^^^^^^^^^^^^^^
  File "C:\Users\james\AppData\Roaming\Python\Python311\site-packages\django\core\checks\urls.py", line 42, in check_url_namespaces_unique
    all_namespaces = _load_all_namespaces(resolver)
                     ^^^^^^^^^^^^^^^^^^^^^^^^^^^^^^
  File "C:\Users\james\AppData\Roaming\Python\Python311\site-packages\django\core\checks\urls.py", line 61, in _load_all_namespaces
    url_patterns = getattr(resolver, "url_patterns", [])
                   ^^^^^^^^^^^^^^^^^^^^^^^^^^^^^^^^^^^^^
  File "C:\Users\james\AppData\Roaming\Python\Python311\site-packages\django\utils\functional.py", line 47, in __get__
    res = instance.__dict__[self.name] = self.func(instance)
                                         ^^^^^^^^^^^^^^^^^^^
  File "C:\Users\james\AppData\Roaming\Python\Python311\site-packages\django\urls\resolvers.py", line 738, in url_patterns
    patterns = getattr(self.urlconf_module, "urlpatterns", self.urlconf_module)
                       ^^^^^^^^^^^^^^^^^^^
  File "C:\Users\james\AppData\Roaming\Python\Python311\site-packages\django\utils\functional.py", line 47, in __get__
    res = instance.__dict__[self.name] = self.func(instance)
                                         ^^^^^^^^^^^^^^^^^^^
  File "C:\Users\james\AppData\Roaming\Python\Python311\site-packages\django\urls\resolvers.py", line 731, in urlconf_module
    return import_module(self.urlconf_name)
           ^^^^^^^^^^^^^^^^^^^^^^^^^^^^^^^^
  File "C:\Python311\Lib\importlib\__init__.py", line 126, in import_module
    return _bootstrap._gcd_import(name[level:], package, level)
           ^^^^^^^^^^^^^^^^^^^^^^^^^^^^^^^^^^^^^^^^^^^^^^^^^^^^
  File "<frozen importlib._bootstrap>", line 1206, in _gcd_import
  File "<frozen importlib._bootstrap>", line 1178, in _find_and_load
  File "<frozen importlib._bootstrap>", line 1149, in _find_and_load_unlocked
  File "<frozen importlib._bootstrap>", line 690, in _load_unlocked
  File "<frozen importlib._bootstrap_external>", line 940, in exec_module
  File "<frozen importlib._bootstrap>", line 241, in _call_with_frames_removed
  File "C:\Users\james\Bootcamp\projects\project-75-emans-wordle\wordle_gato365\wordle_gato365\urls.py", line 19, in <module>
    from users import views as user_views
  File "C:\Users\james\Bootcamp\projects\project-75-emans-wordle\wordle_gato365\users\views.py", line 136
    return render(request, 'users/summary_of_all_games.html', {'summary': summary})
IndentationError: unexpected indent
C:\Users\james\Bootcamp\projects\project-75-emans-wordle\wordle_gato365\users\views.py changed, reloading.
Watching for file changes with StatReloader
Performing system checks...

Exception in thread django-main-thread:
Traceback (most recent call last):
  File "C:\Python311\Lib\threading.py", line 1038, in _bootstrap_inner
    self.run()
  File "C:\Python311\Lib\threading.py", line 975, in run
    self._target(*self._args, **self._kwargs)
  File "C:\Users\james\AppData\Roaming\Python\Python311\site-packages\django\utils\autoreload.py", line 64, in wrapper
    fn(*args, **kwargs)
  File "C:\Users\james\AppData\Roaming\Python\Python311\site-packages\django\core\management\commands\runserver.py", line 133, in inner_run
    self.check(display_num_errors=True)
  File "C:\Users\james\AppData\Roaming\Python\Python311\site-packages\django\core\management\base.py", line 486, in check
    all_issues = checks.run_checks(
                 ^^^^^^^^^^^^^^^^^^
  File "C:\Users\james\AppData\Roaming\Python\Python311\site-packages\django\core\checks\registry.py", line 88, in run_checks
    new_errors = check(app_configs=app_configs, databases=databases)
                 ^^^^^^^^^^^^^^^^^^^^^^^^^^^^^^^^^^^^^^^^^^^^^^^^^^^
  File "C:\Users\james\AppData\Roaming\Python\Python311\site-packages\django\core\checks\urls.py", line 42, in check_url_namespaces_unique
    all_namespaces = _load_all_namespaces(resolver)
                     ^^^^^^^^^^^^^^^^^^^^^^^^^^^^^^
  File "C:\Users\james\AppData\Roaming\Python\Python311\site-packages\django\core\checks\urls.py", line 61, in _load_all_namespaces
    url_patterns = getattr(resolver, "url_patterns", [])
                   ^^^^^^^^^^^^^^^^^^^^^^^^^^^^^^^^^^^^^
  File "C:\Users\james\AppData\Roaming\Python\Python311\site-packages\django\utils\functional.py", line 47, in __get__
    res = instance.__dict__[self.name] = self.func(instance)
                                         ^^^^^^^^^^^^^^^^^^^
  File "C:\Users\james\AppData\Roaming\Python\Python311\site-packages\django\urls\resolvers.py", line 738, in url_patterns
    patterns = getattr(self.urlconf_module, "urlpatterns", self.urlconf_module)
                       ^^^^^^^^^^^^^^^^^^^
  File "C:\Users\james\AppData\Roaming\Python\Python311\site-packages\django\utils\functional.py", line 47, in __get__
    res = instance.__dict__[self.name] = self.func(instance)
                                         ^^^^^^^^^^^^^^^^^^^
  File "C:\Users\james\AppData\Roaming\Python\Python311\site-packages\django\urls\resolvers.py", line 731, in urlconf_module
    return import_module(self.urlconf_name)
           ^^^^^^^^^^^^^^^^^^^^^^^^^^^^^^^^
  File "C:\Python311\Lib\importlib\__init__.py", line 126, in import_module
    return _bootstrap._gcd_import(name[level:], package, level)
           ^^^^^^^^^^^^^^^^^^^^^^^^^^^^^^^^^^^^^^^^^^^^^^^^^^^^
  File "<frozen importlib._bootstrap>", line 1206, in _gcd_import
  File "<frozen importlib._bootstrap>", line 1178, in _find_and_load
  File "<frozen importlib._bootstrap>", line 1149, in _find_and_load_unlocked
  File "<frozen importlib._bootstrap>", line 690, in _load_unlocked
  File "<frozen importlib._bootstrap_external>", line 940, in exec_module
  File "<frozen importlib._bootstrap>", line 241, in _call_with_frames_removed
  File "C:\Users\james\Bootcamp\projects\project-75-emans-wordle\wordle_gato365\wordle_gato365\urls.py", line 19, in <module>
    from users import views as user_views
  File "C:\Users\james\Bootcamp\projects\project-75-emans-wordle\wordle_gato365\users\views.py", line 136
    return render(request, 'users/summary_of_all_games.html', {'summary': summary})
IndentationError: unexpected indent
C:\Users\james\Bootcamp\projects\project-75-emans-wordle\wordle_gato365\users\views.py changed, reloading.
Watching for file changes with StatReloader
Performing system checks...

System check identified no issues (0 silenced).
September 16, 2024 - 13:25:05
Django version 5.0.6, using settings 'wordle_gato365.settings'
Starting development server at http://127.0.0.1:8000/
Quit the server with CTRL-BREAK.

C:\Users\james\Bootcamp\projects\project-75-emans-wordle\wordle_gato365\users\views.py changed, reloading.
Watching for file changes with StatReloader
Performing system checks...

System check identified no issues (0 silenced).
September 16, 2024 - 13:25:12
Django version 5.0.6, using settings 'wordle_gato365.settings'
Starting development server at http://127.0.0.1:8000/
Quit the server with CTRL-BREAK.

"GET /game-history/ HTTP/1.1" 200 4874
"POST /logout/ HTTP/1.1" 302 0
"GET /login/ HTTP/1.1" 200 3850
STREAM b'IHDR' 16 13
STREAM b'eXIf' 41 68
STREAM b'IDAT' 121 65536
"POST /login/ HTTP/1.1" 302 0
"GET /profile/ HTTP/1.1" 200 4295
"GET /game-history/ HTTP/1.1" 200 4874
"GET /game/ HTTP/1.1" 200 3456
"GET /static/wordle/js/scripts.js HTTP/1.1" 304 0
"POST /game/ HTTP/1.1" 200 35
Game 68: Correct word is beach, guess is happy
"POST /submit_guess/ HTTP/1.1" 200 280
Game 68: Correct word is beach, guess is reach
"POST /submit_guess/ HTTP/1.1" 200 282
Game 68: Correct word is beach, guess is teach
"POST /submit_guess/ HTTP/1.1" 200 282
Game 68: Correct word is beach, guess is reach
"POST /submit_guess/ HTTP/1.1" 200 282
Game 68: Correct word is beach, guess is beach
"POST /submit_guess/ HTTP/1.1" 200 284
"POST /update_game_time/ HTTP/1.1" 200 21
"POST /update_guess_times/ HTTP/1.1" 200 21
"GET /game-history/ HTTP/1.1" 200 4874
"GET /game-history/ HTTP/1.1" 200 4874
"GET /static/users/favicon.ico HTTP/1.1" 304 0
C:\Users\james\Bootcamp\projects\project-75-emans-wordle\wordle_gato365\users\views.py changed, reloading.
Watching for file changes with StatReloader
Performing system checks...

System check identified no issues (0 silenced).
September 16, 2024 - 13:30:43
Django version 5.0.6, using settings 'wordle_gato365.settings'
Starting development server at http://127.0.0.1:8000/
Quit the server with CTRL-BREAK.

C:\Users\james\Bootcamp\projects\project-75-emans-wordle\wordle_gato365\users\views.py changed, reloading.
Watching for file changes with StatReloader
Performing system checks...

System check identified no issues (0 silenced).
September 16, 2024 - 13:30:50
Django version 5.0.6, using settings 'wordle_gato365.settings'
Starting development server at http://127.0.0.1:8000/
Quit the server with CTRL-BREAK.

C:\Users\james\Bootcamp\projects\project-75-emans-wordle\wordle_gato365\users\views.py changed, reloading.
Watching for file changes with StatReloader
Performing system checks...

System check identified no issues (0 silenced).
September 16, 2024 - 13:30:56
Django version 5.0.6, using settings 'wordle_gato365.settings'
Starting development server at http://127.0.0.1:8000/
Quit the server with CTRL-BREAK.

C:\Users\james\Bootcamp\projects\project-75-emans-wordle\wordle_gato365\users\views.py changed, reloading.
Watching for file changes with StatReloader
Performing system checks...

Exception in thread django-main-thread:
Traceback (most recent call last):
  File "C:\Python311\Lib\threading.py", line 1038, in _bootstrap_inner
    self.run()
  File "C:\Python311\Lib\threading.py", line 975, in run
    self._target(*self._args, **self._kwargs)
  File "C:\Users\james\AppData\Roaming\Python\Python311\site-packages\django\utils\autoreload.py", line 64, in wrapper
    fn(*args, **kwargs)
  File "C:\Users\james\AppData\Roaming\Python\Python311\site-packages\django\core\management\commands\runserver.py", line 133, in inner_run
    self.check(display_num_errors=True)
  File "C:\Users\james\AppData\Roaming\Python\Python311\site-packages\django\core\management\base.py", line 486, in check
    all_issues = checks.run_checks(
                 ^^^^^^^^^^^^^^^^^^
  File "C:\Users\james\AppData\Roaming\Python\Python311\site-packages\django\core\checks\registry.py", line 88, in run_checks
    new_errors = check(app_configs=app_configs, databases=databases)
                 ^^^^^^^^^^^^^^^^^^^^^^^^^^^^^^^^^^^^^^^^^^^^^^^^^^^
  File "C:\Users\james\AppData\Roaming\Python\Python311\site-packages\django\core\checks\urls.py", line 42, in check_url_namespaces_unique
    all_namespaces = _load_all_namespaces(resolver)
                     ^^^^^^^^^^^^^^^^^^^^^^^^^^^^^^
  File "C:\Users\james\AppData\Roaming\Python\Python311\site-packages\django\core\checks\urls.py", line 61, in _load_all_namespaces
    url_patterns = getattr(resolver, "url_patterns", [])
                   ^^^^^^^^^^^^^^^^^^^^^^^^^^^^^^^^^^^^^
  File "C:\Users\james\AppData\Roaming\Python\Python311\site-packages\django\utils\functional.py", line 47, in __get__
    res = instance.__dict__[self.name] = self.func(instance)
                                         ^^^^^^^^^^^^^^^^^^^
  File "C:\Users\james\AppData\Roaming\Python\Python311\site-packages\django\urls\resolvers.py", line 738, in url_patterns
    patterns = getattr(self.urlconf_module, "urlpatterns", self.urlconf_module)
                       ^^^^^^^^^^^^^^^^^^^
  File "C:\Users\james\AppData\Roaming\Python\Python311\site-packages\django\utils\functional.py", line 47, in __get__
    res = instance.__dict__[self.name] = self.func(instance)
                                         ^^^^^^^^^^^^^^^^^^^
  File "C:\Users\james\AppData\Roaming\Python\Python311\site-packages\django\urls\resolvers.py", line 731, in urlconf_module
    return import_module(self.urlconf_name)
           ^^^^^^^^^^^^^^^^^^^^^^^^^^^^^^^^
  File "C:\Python311\Lib\importlib\__init__.py", line 126, in import_module
    return _bootstrap._gcd_import(name[level:], package, level)
           ^^^^^^^^^^^^^^^^^^^^^^^^^^^^^^^^^^^^^^^^^^^^^^^^^^^^
  File "<frozen importlib._bootstrap>", line 1206, in _gcd_import
  File "<frozen importlib._bootstrap>", line 1178, in _find_and_load
  File "<frozen importlib._bootstrap>", line 1149, in _find_and_load_unlocked
  File "<frozen importlib._bootstrap>", line 690, in _load_unlocked
  File "<frozen importlib._bootstrap_external>", line 940, in exec_module
  File "<frozen importlib._bootstrap>", line 241, in _call_with_frames_removed
  File "C:\Users\james\Bootcamp\projects\project-75-emans-wordle\wordle_gato365\wordle_gato365\urls.py", line 19, in <module>
    from users import views as user_views
  File "C:\Users\james\Bootcamp\projects\project-75-emans-wordle\wordle_gato365\users\views.py", line 134
    `user`: user
    ^
SyntaxError: invalid syntax
C:\Users\james\Bootcamp\projects\project-75-emans-wordle\wordle_gato365\users\views.py changed, reloading.
Watching for file changes with StatReloader
Performing system checks...

System check identified no issues (0 silenced).
September 16, 2024 - 13:31:28
Django version 5.0.6, using settings 'wordle_gato365.settings'
Starting development server at http://127.0.0.1:8000/
Quit the server with CTRL-BREAK.

"GET /game-history/ HTTP/1.1" 200 4870
C:\Users\james\Bootcamp\projects\project-75-emans-wordle\wordle_gato365\users\views.py changed, reloading.
Watching for file changes with StatReloader
Performing system checks...

System check identified no issues (0 silenced).
September 16, 2024 - 13:32:02
Django version 5.0.6, using settings 'wordle_gato365.settings'
Starting development server at http://127.0.0.1:8000/
Quit the server with CTRL-BREAK.

"GET /game-history/ HTTP/1.1" 200 4870
C:\Users\james\Bootcamp\projects\project-75-emans-wordle\wordle_gato365\users\views.py changed, reloading.
Watching for file changes with StatReloader
Performing system checks...

System check identified no issues (0 silenced).
September 16, 2024 - 13:32:15
Django version 5.0.6, using settings 'wordle_gato365.settings'
Starting development server at http://127.0.0.1:8000/
Quit the server with CTRL-BREAK.

C:\Users\james\Bootcamp\projects\project-75-emans-wordle\wordle_gato365\users\views.py changed, reloading.
Watching for file changes with StatReloader
Performing system checks...

System check identified no issues (0 silenced).
September 16, 2024 - 13:32:25
Django version 5.0.6, using settings 'wordle_gato365.settings'
Starting development server at http://127.0.0.1:8000/
Quit the server with CTRL-BREAK.

"GET / HTTP/1.1" 200 3031
"GET /game-history/ HTTP/1.1" 200 4870
C:\Users\james\Bootcamp\projects\project-75-emans-wordle\wordle_gato365\users\views.py changed, reloading.
Watching for file changes with StatReloader
Performing system checks...

System check identified no issues (0 silenced).
September 16, 2024 - 13:35:39
Django version 5.0.6, using settings 'wordle_gato365.settings'
Starting development server at http://127.0.0.1:8000/
Quit the server with CTRL-BREAK.

C:\Users\james\Bootcamp\projects\project-75-emans-wordle\wordle_gato365\users\views.py changed, reloading.
Watching for file changes with StatReloader
Performing system checks...

Exception in thread django-main-thread:
Traceback (most recent call last):
  File "C:\Python311\Lib\threading.py", line 1038, in _bootstrap_inner
    self.run()
  File "C:\Python311\Lib\threading.py", line 975, in run
    self._target(*self._args, **self._kwargs)
  File "C:\Users\james\AppData\Roaming\Python\Python311\site-packages\django\utils\autoreload.py", line 64, in wrapper
    fn(*args, **kwargs)
  File "C:\Users\james\AppData\Roaming\Python\Python311\site-packages\django\core\management\commands\runserver.py", line 133, in inner_run
    self.check(display_num_errors=True)
  File "C:\Users\james\AppData\Roaming\Python\Python311\site-packages\django\core\management\base.py", line 486, in check
    all_issues = checks.run_checks(
                 ^^^^^^^^^^^^^^^^^^
  File "C:\Users\james\AppData\Roaming\Python\Python311\site-packages\django\core\checks\registry.py", line 88, in run_checks
    new_errors = check(app_configs=app_configs, databases=databases)
                 ^^^^^^^^^^^^^^^^^^^^^^^^^^^^^^^^^^^^^^^^^^^^^^^^^^^
  File "C:\Users\james\AppData\Roaming\Python\Python311\site-packages\django\core\checks\urls.py", line 14, in check_url_config
    return check_resolver(resolver)
           ^^^^^^^^^^^^^^^^^^^^^^^^
  File "C:\Users\james\AppData\Roaming\Python\Python311\site-packages\django\core\checks\urls.py", line 24, in check_resolver
    return check_method()
           ^^^^^^^^^^^^^^
  File "C:\Users\james\AppData\Roaming\Python\Python311\site-packages\django\urls\resolvers.py", line 519, in check
    for pattern in self.url_patterns:
                   ^^^^^^^^^^^^^^^^^
  File "C:\Users\james\AppData\Roaming\Python\Python311\site-packages\django\utils\functional.py", line 47, in __get__
    res = instance.__dict__[self.name] = self.func(instance)
                                         ^^^^^^^^^^^^^^^^^^^
  File "C:\Users\james\AppData\Roaming\Python\Python311\site-packages\django\urls\resolvers.py", line 738, in url_patterns
    patterns = getattr(self.urlconf_module, "urlpatterns", self.urlconf_module)
                       ^^^^^^^^^^^^^^^^^^^
  File "C:\Users\james\AppData\Roaming\Python\Python311\site-packages\django\utils\functional.py", line 47, in __get__
    res = instance.__dict__[self.name] = self.func(instance)
                                         ^^^^^^^^^^^^^^^^^^^
  File "C:\Users\james\AppData\Roaming\Python\Python311\site-packages\django\urls\resolvers.py", line 731, in urlconf_module
    return import_module(self.urlconf_name)
           ^^^^^^^^^^^^^^^^^^^^^^^^^^^^^^^^
  File "C:\Python311\Lib\importlib\__init__.py", line 126, in import_module
    return _bootstrap._gcd_import(name[level:], package, level)
           ^^^^^^^^^^^^^^^^^^^^^^^^^^^^^^^^^^^^^^^^^^^^^^^^^^^^
  File "<frozen importlib._bootstrap>", line 1206, in _gcd_import
  File "<frozen importlib._bootstrap>", line 1178, in _find_and_load
  File "<frozen importlib._bootstrap>", line 1149, in _find_and_load_unlocked
  File "<frozen importlib._bootstrap>", line 690, in _load_unlocked
  File "<frozen importlib._bootstrap_external>", line 940, in exec_module
  File "<frozen importlib._bootstrap>", line 241, in _call_with_frames_removed
  File "C:\Users\james\Bootcamp\projects\project-75-emans-wordle\wordle_gato365\wordle_gato365\urls.py", line 42, in <module>
    path('game-history/', user_views.general_game_history, name='game_history'),
                          ^^^^^^^^^^^^^^^^^^^^^^^^^^^^^^^
AttributeError: module 'users.views' has no attribute 'general_game_history'
C:\Users\james\Bootcamp\projects\project-75-emans-wordle\wordle_gato365\users\views.py changed, reloading.
Watching for file changes with StatReloader
Performing system checks...

System check identified no issues (0 silenced).
September 16, 2024 - 13:43:23
Django version 5.0.6, using settings 'wordle_gato365.settings'
Starting development server at http://127.0.0.1:8000/
Quit the server with CTRL-BREAK.

C:\Users\james\Bootcamp\projects\project-75-emans-wordle\wordle_gato365\users\views.py changed, reloading.
Watching for file changes with StatReloader
Performing system checks...

System check identified no issues (0 silenced).
September 16, 2024 - 13:43:27
Django version 5.0.6, using settings 'wordle_gato365.settings'
Starting development server at http://127.0.0.1:8000/
Quit the server with CTRL-BREAK.

"GET /game-history/ HTTP/1.1" 200 10598
"GET /game/ HTTP/1.1" 200 3456
"GET /game-history/ HTTP/1.1" 200 10598
"GET /game-history/ HTTP/1.1" 200 26909
"GET /game-history/ HTTP/1.1" 200 18857
"GET /game/ HTTP/1.1" 200 3456
"POST /game/ HTTP/1.1" 200 35
Game 69: Correct word is beach, guess is shots
"POST /submit_guess/ HTTP/1.1" 200 279
Game 69: Correct word is beach, guess is ghost
"POST /submit_guess/ HTTP/1.1" 200 279
Game 69: Correct word is beach, guess is happy
"POST /submit_guess/ HTTP/1.1" 200 280
Game 69: Correct word is beach, guess is total
"POST /submit_guess/ HTTP/1.1" 200 279
Game 69: Correct word is beach, guess is beach
"POST /submit_guess/ HTTP/1.1" 200 284
"POST /update_game_time/ HTTP/1.1" 200 21
"POST /update_guess_times/ HTTP/1.1" 200 21
"GET /game-history/ HTTP/1.1" 200 19281
"GET /about/ HTTP/1.1" 200 3474
"GET /home/ HTTP/1.1" 200 3031
"GET /game-history/ HTTP/1.1" 200 19281
