Watching for file changes with StatReloader
Performing system checks...

Exception in thread django-main-thread:
Traceback (most recent call last):
  File "C:\Python311\Lib\threading.py", line 1038, in _bootstrap_inner
    self.run()
  File "C:\Python311\Lib\threading.py", line 975, in run
    self._target(*self._args, **self._kwargs)
  File "C:\Users\james\AppData\Roaming\Python\Python311\site-packages\django\utils\autoreload.py", line 64, in wrapper
    fn(*args, **kwargs)
  File "C:\Users\james\AppData\Roaming\Python\Python311\site-packages\django\core\management\commands\runserver.py", line 133, in inner_run
    self.check(display_num_errors=True)
  File "C:\Users\james\AppData\Roaming\Python\Python311\site-packages\django\core\management\base.py", line 486, in check
    all_issues = checks.run_checks(
                 ^^^^^^^^^^^^^^^^^^
  File "C:\Users\james\AppData\Roaming\Python\Python311\site-packages\django\core\checks\registry.py", line 88, in run_checks
    new_errors = check(app_configs=app_configs, databases=databases)
                 ^^^^^^^^^^^^^^^^^^^^^^^^^^^^^^^^^^^^^^^^^^^^^^^^^^^
  File "C:\Users\james\AppData\Roaming\Python\Python311\site-packages\django\core\checks\urls.py", line 42, in check_url_namespaces_unique
    all_namespaces = _load_all_namespaces(resolver)
                     ^^^^^^^^^^^^^^^^^^^^^^^^^^^^^^
  File "C:\Users\james\AppData\Roaming\Python\Python311\site-packages\django\core\checks\urls.py", line 61, in _load_all_namespaces
    url_patterns = getattr(resolver, "url_patterns", [])
                   ^^^^^^^^^^^^^^^^^^^^^^^^^^^^^^^^^^^^^
  File "C:\Users\james\AppData\Roaming\Python\Python311\site-packages\django\utils\functional.py", line 47, in __get__
    res = instance.__dict__[self.name] = self.func(instance)
                                         ^^^^^^^^^^^^^^^^^^^
  File "C:\Users\james\AppData\Roaming\Python\Python311\site-packages\django\urls\resolvers.py", line 738, in url_patterns
    patterns = getattr(self.urlconf_module, "urlpatterns", self.urlconf_module)
                       ^^^^^^^^^^^^^^^^^^^
  File "C:\Users\james\AppData\Roaming\Python\Python311\site-packages\django\utils\functional.py", line 47, in __get__
    res = instance.__dict__[self.name] = self.func(instance)
                                         ^^^^^^^^^^^^^^^^^^^
  File "C:\Users\james\AppData\Roaming\Python\Python311\site-packages\django\urls\resolvers.py", line 731, in urlconf_module
    return import_module(self.urlconf_name)
           ^^^^^^^^^^^^^^^^^^^^^^^^^^^^^^^^
  File "C:\Python311\Lib\importlib\__init__.py", line 126, in import_module
    return _bootstrap._gcd_import(name[level:], package, level)
           ^^^^^^^^^^^^^^^^^^^^^^^^^^^^^^^^^^^^^^^^^^^^^^^^^^^^
  File "<frozen importlib._bootstrap>", line 1206, in _gcd_import
  File "<frozen importlib._bootstrap>", line 1178, in _find_and_load
  File "<frozen importlib._bootstrap>", line 1149, in _find_and_load_unlocked
  File "<frozen importlib._bootstrap>", line 690, in _load_unlocked
  File "<frozen importlib._bootstrap_external>", line 940, in exec_module
  File "<frozen importlib._bootstrap>", line 241, in _call_with_frames_removed
  File "C:\Users\james\Bootcamp\projects\project-75-emans-wordle\wordle_gato365\wordle_gato365\urls.py", line 19, in <module>
    from users import views as user_views
  File "C:\Users\james\Bootcamp\projects\project-75-emans-wordle\wordle_gato365\users\views.py", line 5, in <module>
    from .forms import UserRegisterForm, UserUpdateForm, ProfileUpdateForm
  File "C:\Users\james\Bootcamp\projects\project-75-emans-wordle\wordle_gato365\users\forms.py", line 4, in <module>
    from .models import Profile, CustomUser
ImportError: cannot import name 'CustomUser' from 'users.models' (C:\Users\james\Bootcamp\projects\project-75-emans-wordle\wordle_gato365\users\models.py)
C:\Users\james\Bootcamp\projects\project-75-emans-wordle\wordle_gato365\wordle\models.py changed, reloading.
Watching for file changes with StatReloader
Performing system checks...

Exception in thread django-main-thread:
Traceback (most recent call last):
  File "C:\Python311\Lib\threading.py", line 1038, in _bootstrap_inner
    self.run()
  File "C:\Python311\Lib\threading.py", line 975, in run
    self._target(*self._args, **self._kwargs)
  File "C:\Users\james\AppData\Roaming\Python\Python311\site-packages\django\utils\autoreload.py", line 64, in wrapper
    fn(*args, **kwargs)
  File "C:\Users\james\AppData\Roaming\Python\Python311\site-packages\django\core\management\commands\runserver.py", line 133, in inner_run
    self.check(display_num_errors=True)
  File "C:\Users\james\AppData\Roaming\Python\Python311\site-packages\django\core\management\base.py", line 486, in check
    all_issues = checks.run_checks(
                 ^^^^^^^^^^^^^^^^^^
  File "C:\Users\james\AppData\Roaming\Python\Python311\site-packages\django\core\checks\registry.py", line 88, in run_checks
    new_errors = check(app_configs=app_configs, databases=databases)
                 ^^^^^^^^^^^^^^^^^^^^^^^^^^^^^^^^^^^^^^^^^^^^^^^^^^^
  File "C:\Users\james\AppData\Roaming\Python\Python311\site-packages\django\core\checks\urls.py", line 42, in check_url_namespaces_unique
    all_namespaces = _load_all_namespaces(resolver)
                     ^^^^^^^^^^^^^^^^^^^^^^^^^^^^^^
  File "C:\Users\james\AppData\Roaming\Python\Python311\site-packages\django\core\checks\urls.py", line 61, in _load_all_namespaces
    url_patterns = getattr(resolver, "url_patterns", [])
                   ^^^^^^^^^^^^^^^^^^^^^^^^^^^^^^^^^^^^^
  File "C:\Users\james\AppData\Roaming\Python\Python311\site-packages\django\utils\functional.py", line 47, in __get__
    res = instance.__dict__[self.name] = self.func(instance)
                                         ^^^^^^^^^^^^^^^^^^^
  File "C:\Users\james\AppData\Roaming\Python\Python311\site-packages\django\urls\resolvers.py", line 738, in url_patterns
    patterns = getattr(self.urlconf_module, "urlpatterns", self.urlconf_module)
                       ^^^^^^^^^^^^^^^^^^^
  File "C:\Users\james\AppData\Roaming\Python\Python311\site-packages\django\utils\functional.py", line 47, in __get__
    res = instance.__dict__[self.name] = self.func(instance)
                                         ^^^^^^^^^^^^^^^^^^^
  File "C:\Users\james\AppData\Roaming\Python\Python311\site-packages\django\urls\resolvers.py", line 731, in urlconf_module
    return import_module(self.urlconf_name)
           ^^^^^^^^^^^^^^^^^^^^^^^^^^^^^^^^
  File "C:\Python311\Lib\importlib\__init__.py", line 126, in import_module
    return _bootstrap._gcd_import(name[level:], package, level)
           ^^^^^^^^^^^^^^^^^^^^^^^^^^^^^^^^^^^^^^^^^^^^^^^^^^^^
  File "<frozen importlib._bootstrap>", line 1206, in _gcd_import
  File "<frozen importlib._bootstrap>", line 1178, in _find_and_load
  File "<frozen importlib._bootstrap>", line 1149, in _find_and_load_unlocked
  File "<frozen importlib._bootstrap>", line 690, in _load_unlocked
  File "<frozen importlib._bootstrap_external>", line 940, in exec_module
  File "<frozen importlib._bootstrap>", line 241, in _call_with_frames_removed
  File "C:\Users\james\Bootcamp\projects\project-75-emans-wordle\wordle_gato365\wordle_gato365\urls.py", line 19, in <module>
    from users import views as user_views
  File "C:\Users\james\Bootcamp\projects\project-75-emans-wordle\wordle_gato365\users\views.py", line 5, in <module>
    from .forms import UserRegisterForm, UserUpdateForm, ProfileUpdateForm
  File "C:\Users\james\Bootcamp\projects\project-75-emans-wordle\wordle_gato365\users\forms.py", line 4, in <module>
    from .models import Profile, CustomUser
ImportError: cannot import name 'CustomUser' from 'users.models' (C:\Users\james\Bootcamp\projects\project-75-emans-wordle\wordle_gato365\users\models.py)
C:\Users\james\Bootcamp\projects\project-75-emans-wordle\wordle_gato365\users\models.py changed, reloading.
Watching for file changes with StatReloader
Exception in thread django-main-thread:
Traceback (most recent call last):
  File "C:\Python311\Lib\threading.py", line 1038, in _bootstrap_inner
    self.run()
  File "C:\Python311\Lib\threading.py", line 975, in run
    self._target(*self._args, **self._kwargs)
  File "C:\Users\james\AppData\Roaming\Python\Python311\site-packages\django\utils\autoreload.py", line 64, in wrapper
    fn(*args, **kwargs)
  File "C:\Users\james\AppData\Roaming\Python\Python311\site-packages\django\core\management\commands\runserver.py", line 125, in inner_run
    autoreload.raise_last_exception()
  File "C:\Users\james\AppData\Roaming\Python\Python311\site-packages\django\utils\autoreload.py", line 87, in raise_last_exception
    raise _exception[1]
  File "C:\Users\james\AppData\Roaming\Python\Python311\site-packages\django\core\management\__init__.py", line 394, in execute
    autoreload.check_errors(django.setup)()
  File "C:\Users\james\AppData\Roaming\Python\Python311\site-packages\django\utils\autoreload.py", line 64, in wrapper
    fn(*args, **kwargs)
  File "C:\Users\james\AppData\Roaming\Python\Python311\site-packages\django\__init__.py", line 24, in setup
    apps.populate(settings.INSTALLED_APPS)
  File "C:\Users\james\AppData\Roaming\Python\Python311\site-packages\django\apps\registry.py", line 116, in populate
    app_config.import_models()
  File "C:\Users\james\AppData\Roaming\Python\Python311\site-packages\django\apps\config.py", line 269, in import_models
    self.models_module = import_module(models_module_name)
                         ^^^^^^^^^^^^^^^^^^^^^^^^^^^^^^^^^
  File "C:\Python311\Lib\importlib\__init__.py", line 126, in import_module
    return _bootstrap._gcd_import(name[level:], package, level)
           ^^^^^^^^^^^^^^^^^^^^^^^^^^^^^^^^^^^^^^^^^^^^^^^^^^^^
  File "<frozen importlib._bootstrap>", line 1206, in _gcd_import
  File "<frozen importlib._bootstrap>", line 1178, in _find_and_load
  File "<frozen importlib._bootstrap>", line 1149, in _find_and_load_unlocked
  File "<frozen importlib._bootstrap>", line 690, in _load_unlocked
  File "<frozen importlib._bootstrap_external>", line 940, in exec_module
  File "<frozen importlib._bootstrap>", line 241, in _call_with_frames_removed
  File "C:\Users\james\Bootcamp\projects\project-75-emans-wordle\wordle_gato365\wordle\models.py", line 2, in <module>
    from users.models import User
  File "C:\Users\james\Bootcamp\projects\project-75-emans-wordle\wordle_gato365\users\models.py", line 26, in <module>
    class CustomUser(AbstractUser):
                     ^^^^^^^^^^^^
NameError: name 'AbstractUser' is not defined
C:\Users\james\Bootcamp\projects\project-75-emans-wordle\wordle_gato365\users\models.py changed, reloading.
Watching for file changes with StatReloader
Performing system checks...

Exception in thread django-main-thread:
Traceback (most recent call last):
  File "C:\Python311\Lib\threading.py", line 1038, in _bootstrap_inner
    self.run()
  File "C:\Python311\Lib\threading.py", line 975, in run
    self._target(*self._args, **self._kwargs)
  File "C:\Users\james\AppData\Roaming\Python\Python311\site-packages\django\utils\autoreload.py", line 64, in wrapper
    fn(*args, **kwargs)
  File "C:\Users\james\AppData\Roaming\Python\Python311\site-packages\django\core\management\commands\runserver.py", line 133, in inner_run
    self.check(display_num_errors=True)
  File "C:\Users\james\AppData\Roaming\Python\Python311\site-packages\django\core\management\base.py", line 563, in check
    raise SystemCheckError(msg)
django.core.management.base.SystemCheckError: SystemCheckError: System check identified some issues:

ERRORS:
auth.User.groups: (fields.E304) Reverse accessor 'Group.user_set' for 'auth.User.groups' clashes with reverse accessor for 'users.CustomUser.groups'.
	HINT: Add or change a related_name argument to the definition for 'auth.User.groups' or 'users.CustomUser.groups'.
auth.User.user_permissions: (fields.E304) Reverse accessor 'Permission.user_set' for 'auth.User.user_permissions' clashes with reverse accessor for 'users.CustomUser.user_permissions'.
	HINT: Add or change a related_name argument to the definition for 'auth.User.user_permissions' or 'users.CustomUser.user_permissions'.
users.CustomUser.groups: (fields.E304) Reverse accessor 'Group.user_set' for 'users.CustomUser.groups' clashes with reverse accessor for 'auth.User.groups'.
	HINT: Add or change a related_name argument to the definition for 'users.CustomUser.groups' or 'auth.User.groups'.
users.CustomUser.user_permissions: (fields.E304) Reverse accessor 'Permission.user_set' for 'users.CustomUser.user_permissions' clashes with reverse accessor for 'auth.User.user_permissions'.
	HINT: Add or change a related_name argument to the definition for 'users.CustomUser.user_permissions' or 'auth.User.user_permissions'.
users.CustomUser.user_type: (fields.E009) 'max_length' is too small to fit the longest value in 'choices' (13 characters).

System check identified 5 issues (0 silenced).
C:\Users\james\Bootcamp\projects\project-75-emans-wordle\wordle_gato365\wordle\models.py changed, reloading.
Watching for file changes with StatReloader
Performing system checks...

Exception in thread django-main-thread:
Traceback (most recent call last):
  File "C:\Python311\Lib\threading.py", line 1038, in _bootstrap_inner
    self.run()
  File "C:\Python311\Lib\threading.py", line 975, in run
    self._target(*self._args, **self._kwargs)
  File "C:\Users\james\AppData\Roaming\Python\Python311\site-packages\django\utils\autoreload.py", line 64, in wrapper
    fn(*args, **kwargs)
  File "C:\Users\james\AppData\Roaming\Python\Python311\site-packages\django\core\management\commands\runserver.py", line 133, in inner_run
    self.check(display_num_errors=True)
  File "C:\Users\james\AppData\Roaming\Python\Python311\site-packages\django\core\management\base.py", line 563, in check
    raise SystemCheckError(msg)
django.core.management.base.SystemCheckError: SystemCheckError: System check identified some issues:

ERRORS:
auth.User.groups: (fields.E304) Reverse accessor 'Group.user_set' for 'auth.User.groups' clashes with reverse accessor for 'users.CustomUser.groups'.
	HINT: Add or change a related_name argument to the definition for 'auth.User.groups' or 'users.CustomUser.groups'.
auth.User.user_permissions: (fields.E304) Reverse accessor 'Permission.user_set' for 'auth.User.user_permissions' clashes with reverse accessor for 'users.CustomUser.user_permissions'.
	HINT: Add or change a related_name argument to the definition for 'auth.User.user_permissions' or 'users.CustomUser.user_permissions'.
users.CustomUser.groups: (fields.E304) Reverse accessor 'Group.user_set' for 'users.CustomUser.groups' clashes with reverse accessor for 'auth.User.groups'.
	HINT: Add or change a related_name argument to the definition for 'users.CustomUser.groups' or 'auth.User.groups'.
users.CustomUser.user_permissions: (fields.E304) Reverse accessor 'Permission.user_set' for 'users.CustomUser.user_permissions' clashes with reverse accessor for 'auth.User.user_permissions'.
	HINT: Add or change a related_name argument to the definition for 'users.CustomUser.user_permissions' or 'auth.User.user_permissions'.
users.CustomUser.user_type: (fields.E009) 'max_length' is too small to fit the longest value in 'choices' (13 characters).

System check identified 5 issues (0 silenced).
C:\Users\james\Bootcamp\projects\project-75-emans-wordle\wordle_gato365\users\models.py changed, reloading.
Watching for file changes with StatReloader
Performing system checks...

System check identified no issues (0 silenced).
September 16, 2024 - 15:53:28
Django version 5.0.6, using settings 'wordle_gato365.settings'
Starting development server at http://127.0.0.1:8000/
Quit the server with CTRL-BREAK.

C:\Users\james\Bootcamp\projects\project-75-emans-wordle\wordle_gato365\users\models.py changed, reloading.
Watching for file changes with StatReloader
Performing system checks...

System check identified no issues (0 silenced).
September 16, 2024 - 15:53:38
Django version 5.0.6, using settings 'wordle_gato365.settings'
Starting development server at http://127.0.0.1:8000/
Quit the server with CTRL-BREAK.

C:\Users\james\Bootcamp\projects\project-75-emans-wordle\wordle_gato365\users\models.py changed, reloading.
Watching for file changes with StatReloader
Performing system checks...

System check identified no issues (0 silenced).
September 16, 2024 - 15:53:41
Django version 5.0.6, using settings 'wordle_gato365.settings'
Starting development server at http://127.0.0.1:8000/
Quit the server with CTRL-BREAK.

C:\Users\james\Bootcamp\projects\project-75-emans-wordle\wordle_gato365\users\models.py changed, reloading.
Watching for file changes with StatReloader
Performing system checks...

System check identified no issues (0 silenced).
September 16, 2024 - 15:53:44
Django version 5.0.6, using settings 'wordle_gato365.settings'
Starting development server at http://127.0.0.1:8000/
Quit the server with CTRL-BREAK.

C:\Users\james\Bootcamp\projects\project-75-emans-wordle\wordle_gato365\wordle_gato365\settings.py changed, reloading.
Watching for file changes with StatReloader
Performing system checks...

Exception in thread django-main-thread:
Traceback (most recent call last):
  File "C:\Python311\Lib\threading.py", line 1038, in _bootstrap_inner
    self.run()
  File "C:\Python311\Lib\threading.py", line 975, in run
    self._target(*self._args, **self._kwargs)
  File "C:\Users\james\AppData\Roaming\Python\Python311\site-packages\django\utils\autoreload.py", line 64, in wrapper
    fn(*args, **kwargs)
  File "C:\Users\james\AppData\Roaming\Python\Python311\site-packages\django\core\management\commands\runserver.py", line 133, in inner_run
    self.check(display_num_errors=True)
  File "C:\Users\james\AppData\Roaming\Python\Python311\site-packages\django\core\management\base.py", line 563, in check
    raise SystemCheckError(msg)
django.core.management.base.SystemCheckError: SystemCheckError: System check identified some issues:

ERRORS:
users.Profile.user: (fields.E301) Field defines a relation with the model 'auth.User', which has been swapped out.
	HINT: Update the relation to point at 'settings.AUTH_USER_MODEL'.
wordle.Game.user: (fields.E301) Field defines a relation with the model 'auth.User', which has been swapped out.
	HINT: Update the relation to point at 'settings.AUTH_USER_MODEL'.

System check identified 2 issues (0 silenced).
C:\Users\james\Bootcamp\projects\project-75-emans-wordle\wordle_gato365\wordle_gato365\settings.py changed, reloading.
Watching for file changes with StatReloader
Performing system checks...

System check identified no issues (0 silenced).
September 16, 2024 - 15:54:51
Django version 5.0.6, using settings 'wordle_gato365.settings'
Starting development server at http://127.0.0.1:8000/
Quit the server with CTRL-BREAK.

C:\Users\james\Bootcamp\projects\project-75-emans-wordle\wordle_gato365\wordle_gato365\settings.py changed, reloading.
Watching for file changes with StatReloader
Performing system checks...

Exception in thread django-main-thread:
Traceback (most recent call last):
  File "C:\Python311\Lib\threading.py", line 1038, in _bootstrap_inner
    self.run()
  File "C:\Python311\Lib\threading.py", line 975, in run
    self._target(*self._args, **self._kwargs)
  File "C:\Users\james\AppData\Roaming\Python\Python311\site-packages\django\utils\autoreload.py", line 64, in wrapper
    fn(*args, **kwargs)
  File "C:\Users\james\AppData\Roaming\Python\Python311\site-packages\django\core\management\commands\runserver.py", line 133, in inner_run
    self.check(display_num_errors=True)
  File "C:\Users\james\AppData\Roaming\Python\Python311\site-packages\django\core\management\base.py", line 563, in check
    raise SystemCheckError(msg)
django.core.management.base.SystemCheckError: SystemCheckError: System check identified some issues:

ERRORS:
users.Profile.user: (fields.E301) Field defines a relation with the model 'auth.User', which has been swapped out.
	HINT: Update the relation to point at 'settings.AUTH_USER_MODEL'.
wordle.Game.user: (fields.E301) Field defines a relation with the model 'auth.User', which has been swapped out.
	HINT: Update the relation to point at 'settings.AUTH_USER_MODEL'.

System check identified 2 issues (0 silenced).
C:\Users\james\Bootcamp\projects\project-75-emans-wordle\wordle_gato365\users\admin.py changed, reloading.
Watching for file changes with StatReloader
Performing system checks...

Exception in thread django-main-thread:
Traceback (most recent call last):
  File "C:\Python311\Lib\threading.py", line 1038, in _bootstrap_inner
    self.run()
  File "C:\Python311\Lib\threading.py", line 975, in run
    self._target(*self._args, **self._kwargs)
  File "C:\Users\james\AppData\Roaming\Python\Python311\site-packages\django\utils\autoreload.py", line 64, in wrapper
    fn(*args, **kwargs)
  File "C:\Users\james\AppData\Roaming\Python\Python311\site-packages\django\core\management\commands\runserver.py", line 133, in inner_run
    self.check(display_num_errors=True)
  File "C:\Users\james\AppData\Roaming\Python\Python311\site-packages\django\core\management\base.py", line 563, in check
    raise SystemCheckError(msg)
django.core.management.base.SystemCheckError: SystemCheckError: System check identified some issues:

ERRORS:
users.Profile.user: (fields.E301) Field defines a relation with the model 'auth.User', which has been swapped out.
	HINT: Update the relation to point at 'settings.AUTH_USER_MODEL'.
wordle.Game.user: (fields.E301) Field defines a relation with the model 'auth.User', which has been swapped out.
	HINT: Update the relation to point at 'settings.AUTH_USER_MODEL'.

System check identified 2 issues (0 silenced).
C:\Users\james\Bootcamp\projects\project-75-emans-wordle\wordle_gato365\users\admin.py changed, reloading.
Watching for file changes with StatReloader
Exception in thread django-main-thread:
Traceback (most recent call last):
  File "C:\Python311\Lib\threading.py", line 1038, in _bootstrap_inner
    self.run()
  File "C:\Python311\Lib\threading.py", line 975, in run
    self._target(*self._args, **self._kwargs)
  File "C:\Users\james\AppData\Roaming\Python\Python311\site-packages\django\utils\autoreload.py", line 64, in wrapper
    fn(*args, **kwargs)
  File "C:\Users\james\AppData\Roaming\Python\Python311\site-packages\django\core\management\commands\runserver.py", line 125, in inner_run
    autoreload.raise_last_exception()
  File "C:\Users\james\AppData\Roaming\Python\Python311\site-packages\django\utils\autoreload.py", line 87, in raise_last_exception
    raise _exception[1]
  File "C:\Users\james\AppData\Roaming\Python\Python311\site-packages\django\core\management\__init__.py", line 394, in execute
    autoreload.check_errors(django.setup)()
  File "C:\Users\james\AppData\Roaming\Python\Python311\site-packages\django\utils\autoreload.py", line 64, in wrapper
    fn(*args, **kwargs)
  File "C:\Users\james\AppData\Roaming\Python\Python311\site-packages\django\__init__.py", line 24, in setup
    apps.populate(settings.INSTALLED_APPS)
  File "C:\Users\james\AppData\Roaming\Python\Python311\site-packages\django\apps\registry.py", line 124, in populate
    app_config.ready()
  File "C:\Users\james\AppData\Roaming\Python\Python311\site-packages\django\contrib\admin\apps.py", line 27, in ready
    self.module.autodiscover()
  File "C:\Users\james\AppData\Roaming\Python\Python311\site-packages\django\contrib\admin\__init__.py", line 52, in autodiscover
    autodiscover_modules("admin", register_to=site)
  File "C:\Users\james\AppData\Roaming\Python\Python311\site-packages\django\utils\module_loading.py", line 58, in autodiscover_modules
    import_module("%s.%s" % (app_config.name, module_to_search))
  File "C:\Python311\Lib\importlib\__init__.py", line 126, in import_module
    return _bootstrap._gcd_import(name[level:], package, level)
           ^^^^^^^^^^^^^^^^^^^^^^^^^^^^^^^^^^^^^^^^^^^^^^^^^^^^
  File "<frozen importlib._bootstrap>", line 1206, in _gcd_import
  File "<frozen importlib._bootstrap>", line 1178, in _find_and_load
  File "<frozen importlib._bootstrap>", line 1149, in _find_and_load_unlocked
  File "<frozen importlib._bootstrap>", line 690, in _load_unlocked
  File "<frozen importlib._bootstrap_external>", line 940, in exec_module
  File "<frozen importlib._bootstrap>", line 241, in _call_with_frames_removed
  File "C:\Users\james\Bootcamp\projects\project-75-emans-wordle\wordle_gato365\users\admin.py", line 3, in <module>
    f
NameError: name 'f' is not defined
C:\Users\james\Bootcamp\projects\project-75-emans-wordle\wordle_gato365\users\admin.py changed, reloading.
Watching for file changes with StatReloader
Performing system checks...

Exception in thread django-main-thread:
Traceback (most recent call last):
  File "C:\Python311\Lib\threading.py", line 1038, in _bootstrap_inner
    self.run()
  File "C:\Python311\Lib\threading.py", line 975, in run
    self._target(*self._args, **self._kwargs)
  File "C:\Users\james\AppData\Roaming\Python\Python311\site-packages\django\utils\autoreload.py", line 64, in wrapper
    fn(*args, **kwargs)
  File "C:\Users\james\AppData\Roaming\Python\Python311\site-packages\django\core\management\commands\runserver.py", line 133, in inner_run
    self.check(display_num_errors=True)
  File "C:\Users\james\AppData\Roaming\Python\Python311\site-packages\django\core\management\base.py", line 563, in check
    raise SystemCheckError(msg)
django.core.management.base.SystemCheckError: SystemCheckError: System check identified some issues:

ERRORS:
users.Profile.user: (fields.E301) Field defines a relation with the model 'auth.User', which has been swapped out.
	HINT: Update the relation to point at 'settings.AUTH_USER_MODEL'.
wordle.Game.user: (fields.E301) Field defines a relation with the model 'auth.User', which has been swapped out.
	HINT: Update the relation to point at 'settings.AUTH_USER_MODEL'.

System check identified 2 issues (0 silenced).
C:\Users\james\Bootcamp\projects\project-75-emans-wordle\wordle_gato365\users\admin.py changed, reloading.
Watching for file changes with StatReloader
Exception in thread django-main-thread:
Traceback (most recent call last):
  File "C:\Python311\Lib\threading.py", line 1038, in _bootstrap_inner
    self.run()
  File "C:\Python311\Lib\threading.py", line 975, in run
    self._target(*self._args, **self._kwargs)
  File "C:\Users\james\AppData\Roaming\Python\Python311\site-packages\django\utils\autoreload.py", line 64, in wrapper
    fn(*args, **kwargs)
  File "C:\Users\james\AppData\Roaming\Python\Python311\site-packages\django\core\management\commands\runserver.py", line 125, in inner_run
    autoreload.raise_last_exception()
  File "C:\Users\james\AppData\Roaming\Python\Python311\site-packages\django\utils\autoreload.py", line 87, in raise_last_exception
    raise _exception[1]
  File "C:\Users\james\AppData\Roaming\Python\Python311\site-packages\django\core\management\__init__.py", line 394, in execute
    autoreload.check_errors(django.setup)()
  File "C:\Users\james\AppData\Roaming\Python\Python311\site-packages\django\utils\autoreload.py", line 64, in wrapper
    fn(*args, **kwargs)
  File "C:\Users\james\AppData\Roaming\Python\Python311\site-packages\django\__init__.py", line 24, in setup
    apps.populate(settings.INSTALLED_APPS)
  File "C:\Users\james\AppData\Roaming\Python\Python311\site-packages\django\apps\registry.py", line 124, in populate
    app_config.ready()
  File "C:\Users\james\AppData\Roaming\Python\Python311\site-packages\django\contrib\admin\apps.py", line 27, in ready
    self.module.autodiscover()
  File "C:\Users\james\AppData\Roaming\Python\Python311\site-packages\django\contrib\admin\__init__.py", line 52, in autodiscover
    autodiscover_modules("admin", register_to=site)
  File "C:\Users\james\AppData\Roaming\Python\Python311\site-packages\django\utils\module_loading.py", line 58, in autodiscover_modules
    import_module("%s.%s" % (app_config.name, module_to_search))
  File "C:\Python311\Lib\importlib\__init__.py", line 126, in import_module
    return _bootstrap._gcd_import(name[level:], package, level)
           ^^^^^^^^^^^^^^^^^^^^^^^^^^^^^^^^^^^^^^^^^^^^^^^^^^^^
  File "<frozen importlib._bootstrap>", line 1206, in _gcd_import
  File "<frozen importlib._bootstrap>", line 1178, in _find_and_load
  File "<frozen importlib._bootstrap>", line 1149, in _find_and_load_unlocked
  File "<frozen importlib._bootstrap>", line 690, in _load_unlocked
  File "<frozen importlib._bootstrap_external>", line 936, in exec_module
  File "<frozen importlib._bootstrap_external>", line 1074, in get_code
  File "<frozen importlib._bootstrap_external>", line 1004, in source_to_code
  File "<frozen importlib._bootstrap>", line 241, in _call_with_frames_removed
  File "C:\Users\james\Bootcamp\projects\project-75-emans-wordle\wordle_gato365\users\admin.py", line 3
    from .models import CustomUsert Profile
                                    ^^^^^^^
SyntaxError: invalid syntax
C:\Users\james\Bootcamp\projects\project-75-emans-wordle\wordle_gato365\users\admin.py changed, reloading.
Watching for file changes with StatReloader
Exception in thread django-main-thread:
Traceback (most recent call last):
  File "C:\Python311\Lib\threading.py", line 1038, in _bootstrap_inner
    self.run()
  File "C:\Python311\Lib\threading.py", line 975, in run
    self._target(*self._args, **self._kwargs)
  File "C:\Users\james\AppData\Roaming\Python\Python311\site-packages\django\utils\autoreload.py", line 64, in wrapper
    fn(*args, **kwargs)
  File "C:\Users\james\AppData\Roaming\Python\Python311\site-packages\django\core\management\commands\runserver.py", line 125, in inner_run
    autoreload.raise_last_exception()
  File "C:\Users\james\AppData\Roaming\Python\Python311\site-packages\django\utils\autoreload.py", line 87, in raise_last_exception
    raise _exception[1]
  File "C:\Users\james\AppData\Roaming\Python\Python311\site-packages\django\core\management\__init__.py", line 394, in execute
    autoreload.check_errors(django.setup)()
  File "C:\Users\james\AppData\Roaming\Python\Python311\site-packages\django\utils\autoreload.py", line 64, in wrapper
    fn(*args, **kwargs)
  File "C:\Users\james\AppData\Roaming\Python\Python311\site-packages\django\__init__.py", line 24, in setup
    apps.populate(settings.INSTALLED_APPS)
  File "C:\Users\james\AppData\Roaming\Python\Python311\site-packages\django\apps\registry.py", line 124, in populate
    app_config.ready()
  File "C:\Users\james\AppData\Roaming\Python\Python311\site-packages\django\contrib\admin\apps.py", line 27, in ready
    self.module.autodiscover()
  File "C:\Users\james\AppData\Roaming\Python\Python311\site-packages\django\contrib\admin\__init__.py", line 52, in autodiscover
    autodiscover_modules("admin", register_to=site)
  File "C:\Users\james\AppData\Roaming\Python\Python311\site-packages\django\utils\module_loading.py", line 58, in autodiscover_modules
    import_module("%s.%s" % (app_config.name, module_to_search))
  File "C:\Python311\Lib\importlib\__init__.py", line 126, in import_module
    return _bootstrap._gcd_import(name[level:], package, level)
           ^^^^^^^^^^^^^^^^^^^^^^^^^^^^^^^^^^^^^^^^^^^^^^^^^^^^
  File "<frozen importlib._bootstrap>", line 1206, in _gcd_import
  File "<frozen importlib._bootstrap>", line 1178, in _find_and_load
  File "<frozen importlib._bootstrap>", line 1149, in _find_and_load_unlocked
  File "<frozen importlib._bootstrap>", line 690, in _load_unlocked
  File "<frozen importlib._bootstrap_external>", line 936, in exec_module
  File "<frozen importlib._bootstrap_external>", line 1074, in get_code
  File "<frozen importlib._bootstrap_external>", line 1004, in source_to_code
  File "<frozen importlib._bootstrap>", line 241, in _call_with_frames_removed
  File "C:\Users\james\Bootcamp\projects\project-75-emans-wordle\wordle_gato365\users\admin.py", line 3
    from .models import CustomUsert Profile
                                    ^^^^^^^
SyntaxError: invalid syntax
C:\Users\james\Bootcamp\projects\project-75-emans-wordle\wordle_gato365\users\admin.py changed, reloading.
Watching for file changes with StatReloader
Exception in thread django-main-thread:
Traceback (most recent call last):
  File "C:\Python311\Lib\threading.py", line 1038, in _bootstrap_inner
    self.run()
  File "C:\Python311\Lib\threading.py", line 975, in run
    self._target(*self._args, **self._kwargs)
  File "C:\Users\james\AppData\Roaming\Python\Python311\site-packages\django\utils\autoreload.py", line 64, in wrapper
    fn(*args, **kwargs)
  File "C:\Users\james\AppData\Roaming\Python\Python311\site-packages\django\core\management\commands\runserver.py", line 125, in inner_run
    autoreload.raise_last_exception()
  File "C:\Users\james\AppData\Roaming\Python\Python311\site-packages\django\utils\autoreload.py", line 87, in raise_last_exception
    raise _exception[1]
  File "C:\Users\james\AppData\Roaming\Python\Python311\site-packages\django\core\management\__init__.py", line 394, in execute
    autoreload.check_errors(django.setup)()
  File "C:\Users\james\AppData\Roaming\Python\Python311\site-packages\django\utils\autoreload.py", line 64, in wrapper
    fn(*args, **kwargs)
  File "C:\Users\james\AppData\Roaming\Python\Python311\site-packages\django\__init__.py", line 24, in setup
    apps.populate(settings.INSTALLED_APPS)
  File "C:\Users\james\AppData\Roaming\Python\Python311\site-packages\django\apps\registry.py", line 124, in populate
    app_config.ready()
  File "C:\Users\james\AppData\Roaming\Python\Python311\site-packages\django\contrib\admin\apps.py", line 27, in ready
    self.module.autodiscover()
  File "C:\Users\james\AppData\Roaming\Python\Python311\site-packages\django\contrib\admin\__init__.py", line 52, in autodiscover
    autodiscover_modules("admin", register_to=site)
  File "C:\Users\james\AppData\Roaming\Python\Python311\site-packages\django\utils\module_loading.py", line 58, in autodiscover_modules
    import_module("%s.%s" % (app_config.name, module_to_search))
  File "C:\Python311\Lib\importlib\__init__.py", line 126, in import_module
    return _bootstrap._gcd_import(name[level:], package, level)
           ^^^^^^^^^^^^^^^^^^^^^^^^^^^^^^^^^^^^^^^^^^^^^^^^^^^^
  File "<frozen importlib._bootstrap>", line 1206, in _gcd_import
  File "<frozen importlib._bootstrap>", line 1178, in _find_and_load
  File "<frozen importlib._bootstrap>", line 1149, in _find_and_load_unlocked
  File "<frozen importlib._bootstrap>", line 690, in _load_unlocked
  File "<frozen importlib._bootstrap_external>", line 936, in exec_module
  File "<frozen importlib._bootstrap_external>", line 1074, in get_code
  File "<frozen importlib._bootstrap_external>", line 1004, in source_to_code
  File "<frozen importlib._bootstrap>", line 241, in _call_with_frames_removed
  File "C:\Users\james\Bootcamp\projects\project-75-emans-wordle\wordle_gato365\users\admin.py", line 3
    from .models import CustomUser Profile
                                   ^^^^^^^
SyntaxError: invalid syntax
C:\Users\james\Bootcamp\projects\project-75-emans-wordle\wordle_gato365\users\admin.py changed, reloading.
Watching for file changes with StatReloader
Performing system checks...

Exception in thread django-main-thread:
Traceback (most recent call last):
  File "C:\Python311\Lib\threading.py", line 1038, in _bootstrap_inner
    self.run()
  File "C:\Python311\Lib\threading.py", line 975, in run
    self._target(*self._args, **self._kwargs)
  File "C:\Users\james\AppData\Roaming\Python\Python311\site-packages\django\utils\autoreload.py", line 64, in wrapper
    fn(*args, **kwargs)
  File "C:\Users\james\AppData\Roaming\Python\Python311\site-packages\django\core\management\commands\runserver.py", line 133, in inner_run
    self.check(display_num_errors=True)
  File "C:\Users\james\AppData\Roaming\Python\Python311\site-packages\django\core\management\base.py", line 563, in check
    raise SystemCheckError(msg)
django.core.management.base.SystemCheckError: SystemCheckError: System check identified some issues:

ERRORS:
users.Profile.user: (fields.E301) Field defines a relation with the model 'auth.User', which has been swapped out.
	HINT: Update the relation to point at 'settings.AUTH_USER_MODEL'.
wordle.Game.user: (fields.E301) Field defines a relation with the model 'auth.User', which has been swapped out.
	HINT: Update the relation to point at 'settings.AUTH_USER_MODEL'.

System check identified 2 issues (0 silenced).
C:\Users\james\Bootcamp\projects\project-75-emans-wordle\wordle_gato365\users\admin.py changed, reloading.
Watching for file changes with StatReloader
Performing system checks...

Exception in thread django-main-thread:
Traceback (most recent call last):
  File "C:\Python311\Lib\threading.py", line 1038, in _bootstrap_inner
    self.run()
  File "C:\Python311\Lib\threading.py", line 975, in run
    self._target(*self._args, **self._kwargs)
  File "C:\Users\james\AppData\Roaming\Python\Python311\site-packages\django\utils\autoreload.py", line 64, in wrapper
    fn(*args, **kwargs)
  File "C:\Users\james\AppData\Roaming\Python\Python311\site-packages\django\core\management\commands\runserver.py", line 133, in inner_run
    self.check(display_num_errors=True)
  File "C:\Users\james\AppData\Roaming\Python\Python311\site-packages\django\core\management\base.py", line 563, in check
    raise SystemCheckError(msg)
django.core.management.base.SystemCheckError: SystemCheckError: System check identified some issues:

ERRORS:
users.Profile.user: (fields.E301) Field defines a relation with the model 'auth.User', which has been swapped out.
	HINT: Update the relation to point at 'settings.AUTH_USER_MODEL'.
wordle.Game.user: (fields.E301) Field defines a relation with the model 'auth.User', which has been swapped out.
	HINT: Update the relation to point at 'settings.AUTH_USER_MODEL'.

System check identified 2 issues (0 silenced).
C:\Users\james\Bootcamp\projects\project-75-emans-wordle\wordle_gato365\users\admin.py changed, reloading.
Watching for file changes with StatReloader
Exception in thread django-main-thread:
Traceback (most recent call last):
  File "C:\Python311\Lib\threading.py", line 1038, in _bootstrap_inner
    self.run()
  File "C:\Python311\Lib\threading.py", line 975, in run
    self._target(*self._args, **self._kwargs)
  File "C:\Users\james\AppData\Roaming\Python\Python311\site-packages\django\utils\autoreload.py", line 64, in wrapper
    fn(*args, **kwargs)
  File "C:\Users\james\AppData\Roaming\Python\Python311\site-packages\django\core\management\commands\runserver.py", line 125, in inner_run
    autoreload.raise_last_exception()
  File "C:\Users\james\AppData\Roaming\Python\Python311\site-packages\django\utils\autoreload.py", line 87, in raise_last_exception
    raise _exception[1]
  File "C:\Users\james\AppData\Roaming\Python\Python311\site-packages\django\core\management\__init__.py", line 394, in execute
    autoreload.check_errors(django.setup)()
  File "C:\Users\james\AppData\Roaming\Python\Python311\site-packages\django\utils\autoreload.py", line 64, in wrapper
    fn(*args, **kwargs)
  File "C:\Users\james\AppData\Roaming\Python\Python311\site-packages\django\__init__.py", line 24, in setup
    apps.populate(settings.INSTALLED_APPS)
  File "C:\Users\james\AppData\Roaming\Python\Python311\site-packages\django\apps\registry.py", line 124, in populate
    app_config.ready()
  File "C:\Users\james\AppData\Roaming\Python\Python311\site-packages\django\contrib\admin\apps.py", line 27, in ready
    self.module.autodiscover()
  File "C:\Users\james\AppData\Roaming\Python\Python311\site-packages\django\contrib\admin\__init__.py", line 52, in autodiscover
    autodiscover_modules("admin", register_to=site)
  File "C:\Users\james\AppData\Roaming\Python\Python311\site-packages\django\utils\module_loading.py", line 58, in autodiscover_modules
    import_module("%s.%s" % (app_config.name, module_to_search))
  File "C:\Python311\Lib\importlib\__init__.py", line 126, in import_module
    return _bootstrap._gcd_import(name[level:], package, level)
           ^^^^^^^^^^^^^^^^^^^^^^^^^^^^^^^^^^^^^^^^^^^^^^^^^^^^
  File "<frozen importlib._bootstrap>", line 1206, in _gcd_import
  File "<frozen importlib._bootstrap>", line 1178, in _find_and_load
  File "<frozen importlib._bootstrap>", line 1149, in _find_and_load_unlocked
  File "<frozen importlib._bootstrap>", line 690, in _load_unlocked
  File "<frozen importlib._bootstrap_external>", line 936, in exec_module
  File "<frozen importlib._bootstrap_external>", line 1074, in get_code
  File "<frozen importlib._bootstrap_external>", line 1004, in source_to_code
  File "<frozen importlib._bootstrap>", line 241, in _call_with_frames_removed
  File "C:\Users\james\Bootcamp\projects\project-75-emans-wordle\wordle_gato365\users\admin.py", line 3
    from .models import CustomUser Profile
                                   ^^^^^^^
SyntaxError: invalid syntax
C:\Users\james\Bootcamp\projects\project-75-emans-wordle\wordle_gato365\users\admin.py changed, reloading.
Watching for file changes with StatReloader
Performing system checks...

Exception in thread django-main-thread:
Traceback (most recent call last):
  File "C:\Python311\Lib\threading.py", line 1038, in _bootstrap_inner
    self.run()
  File "C:\Python311\Lib\threading.py", line 975, in run
    self._target(*self._args, **self._kwargs)
  File "C:\Users\james\AppData\Roaming\Python\Python311\site-packages\django\utils\autoreload.py", line 64, in wrapper
    fn(*args, **kwargs)
  File "C:\Users\james\AppData\Roaming\Python\Python311\site-packages\django\core\management\commands\runserver.py", line 133, in inner_run
    self.check(display_num_errors=True)
  File "C:\Users\james\AppData\Roaming\Python\Python311\site-packages\django\core\management\base.py", line 563, in check
    raise SystemCheckError(msg)
django.core.management.base.SystemCheckError: SystemCheckError: System check identified some issues:

ERRORS:
users.Profile.user: (fields.E301) Field defines a relation with the model 'auth.User', which has been swapped out.
	HINT: Update the relation to point at 'settings.AUTH_USER_MODEL'.
wordle.Game.user: (fields.E301) Field defines a relation with the model 'auth.User', which has been swapped out.
	HINT: Update the relation to point at 'settings.AUTH_USER_MODEL'.

System check identified 2 issues (0 silenced).
C:\Users\james\Bootcamp\projects\project-75-emans-wordle\wordle_gato365\users\admin.py changed, reloading.
Watching for file changes with StatReloader
Performing system checks...

Exception in thread django-main-thread:
Traceback (most recent call last):
  File "C:\Python311\Lib\threading.py", line 1038, in _bootstrap_inner
    self.run()
  File "C:\Python311\Lib\threading.py", line 975, in run
    self._target(*self._args, **self._kwargs)
  File "C:\Users\james\AppData\Roaming\Python\Python311\site-packages\django\utils\autoreload.py", line 64, in wrapper
    fn(*args, **kwargs)
  File "C:\Users\james\AppData\Roaming\Python\Python311\site-packages\django\core\management\commands\runserver.py", line 133, in inner_run
    self.check(display_num_errors=True)
  File "C:\Users\james\AppData\Roaming\Python\Python311\site-packages\django\core\management\base.py", line 563, in check
    raise SystemCheckError(msg)
django.core.management.base.SystemCheckError: SystemCheckError: System check identified some issues:

ERRORS:
users.Profile.user: (fields.E301) Field defines a relation with the model 'auth.User', which has been swapped out.
	HINT: Update the relation to point at 'settings.AUTH_USER_MODEL'.
wordle.Game.user: (fields.E301) Field defines a relation with the model 'auth.User', which has been swapped out.
	HINT: Update the relation to point at 'settings.AUTH_USER_MODEL'.

System check identified 2 issues (0 silenced).
C:\Users\james\Bootcamp\projects\project-75-emans-wordle\wordle_gato365\users\admin.py changed, reloading.
Watching for file changes with StatReloader
Performing system checks...

Exception in thread django-main-thread:
Traceback (most recent call last):
  File "C:\Python311\Lib\threading.py", line 1038, in _bootstrap_inner
    self.run()
  File "C:\Python311\Lib\threading.py", line 975, in run
    self._target(*self._args, **self._kwargs)
  File "C:\Users\james\AppData\Roaming\Python\Python311\site-packages\django\utils\autoreload.py", line 64, in wrapper
    fn(*args, **kwargs)
  File "C:\Users\james\AppData\Roaming\Python\Python311\site-packages\django\core\management\commands\runserver.py", line 133, in inner_run
    self.check(display_num_errors=True)
  File "C:\Users\james\AppData\Roaming\Python\Python311\site-packages\django\core\management\base.py", line 563, in check
    raise SystemCheckError(msg)
django.core.management.base.SystemCheckError: SystemCheckError: System check identified some issues:

ERRORS:
<class 'users.admin.ProfileInline'>: (admin.E202) 'users.Profile' has no ForeignKey to 'users.CustomUser'.
users.Profile.user: (fields.E301) Field defines a relation with the model 'auth.User', which has been swapped out.
	HINT: Update the relation to point at 'settings.AUTH_USER_MODEL'.
wordle.Game.user: (fields.E301) Field defines a relation with the model 'auth.User', which has been swapped out.
	HINT: Update the relation to point at 'settings.AUTH_USER_MODEL'.

System check identified 3 issues (0 silenced).
C:\Users\james\Bootcamp\projects\project-75-emans-wordle\wordle_gato365\users\admin.py changed, reloading.
Watching for file changes with StatReloader
Performing system checks...

Exception in thread django-main-thread:
Traceback (most recent call last):
  File "C:\Python311\Lib\threading.py", line 1038, in _bootstrap_inner
    self.run()
  File "C:\Python311\Lib\threading.py", line 975, in run
    self._target(*self._args, **self._kwargs)
  File "C:\Users\james\AppData\Roaming\Python\Python311\site-packages\django\utils\autoreload.py", line 64, in wrapper
    fn(*args, **kwargs)
  File "C:\Users\james\AppData\Roaming\Python\Python311\site-packages\django\core\management\commands\runserver.py", line 133, in inner_run
    self.check(display_num_errors=True)
  File "C:\Users\james\AppData\Roaming\Python\Python311\site-packages\django\core\management\base.py", line 563, in check
    raise SystemCheckError(msg)
django.core.management.base.SystemCheckError: SystemCheckError: System check identified some issues:

ERRORS:
<class 'users.admin.ProfileInline'>: (admin.E202) 'users.Profile' has no ForeignKey to 'users.CustomUser'.
users.Profile.user: (fields.E301) Field defines a relation with the model 'auth.User', which has been swapped out.
	HINT: Update the relation to point at 'settings.AUTH_USER_MODEL'.
wordle.Game.user: (fields.E301) Field defines a relation with the model 'auth.User', which has been swapped out.
	HINT: Update the relation to point at 'settings.AUTH_USER_MODEL'.

System check identified 3 issues (0 silenced).
C:\Users\james\Bootcamp\projects\project-75-emans-wordle\wordle_gato365\users\admin.py changed, reloading.
Watching for file changes with StatReloader
Performing system checks...

Exception in thread django-main-thread:
Traceback (most recent call last):
  File "C:\Python311\Lib\threading.py", line 1038, in _bootstrap_inner
    self.run()
  File "C:\Python311\Lib\threading.py", line 975, in run
    self._target(*self._args, **self._kwargs)
  File "C:\Users\james\AppData\Roaming\Python\Python311\site-packages\django\utils\autoreload.py", line 64, in wrapper
    fn(*args, **kwargs)
  File "C:\Users\james\AppData\Roaming\Python\Python311\site-packages\django\core\management\commands\runserver.py", line 133, in inner_run
    self.check(display_num_errors=True)
  File "C:\Users\james\AppData\Roaming\Python\Python311\site-packages\django\core\management\base.py", line 563, in check
    raise SystemCheckError(msg)
django.core.management.base.SystemCheckError: SystemCheckError: System check identified some issues:

ERRORS:
<class 'users.admin.ProfileInline'>: (admin.E202) 'users.Profile' has no ForeignKey to 'users.CustomUser'.
users.Profile.user: (fields.E301) Field defines a relation with the model 'auth.User', which has been swapped out.
	HINT: Update the relation to point at 'settings.AUTH_USER_MODEL'.
wordle.Game.user: (fields.E301) Field defines a relation with the model 'auth.User', which has been swapped out.
	HINT: Update the relation to point at 'settings.AUTH_USER_MODEL'.

System check identified 3 issues (0 silenced).
C:\Users\james\Bootcamp\projects\project-75-emans-wordle\wordle_gato365\users\admin.py changed, reloading.
Watching for file changes with StatReloader
Performing system checks...

Exception in thread django-main-thread:
Traceback (most recent call last):
  File "C:\Python311\Lib\threading.py", line 1038, in _bootstrap_inner
    self.run()
  File "C:\Python311\Lib\threading.py", line 975, in run
    self._target(*self._args, **self._kwargs)
  File "C:\Users\james\AppData\Roaming\Python\Python311\site-packages\django\utils\autoreload.py", line 64, in wrapper
    fn(*args, **kwargs)
  File "C:\Users\james\AppData\Roaming\Python\Python311\site-packages\django\core\management\commands\runserver.py", line 133, in inner_run
    self.check(display_num_errors=True)
  File "C:\Users\james\AppData\Roaming\Python\Python311\site-packages\django\core\management\base.py", line 563, in check
    raise SystemCheckError(msg)
django.core.management.base.SystemCheckError: SystemCheckError: System check identified some issues:

ERRORS:
<class 'users.admin.ProfileInline'>: (admin.E202) 'users.Profile' has no ForeignKey to 'users.CustomUser'.
users.Profile.user: (fields.E301) Field defines a relation with the model 'auth.User', which has been swapped out.
	HINT: Update the relation to point at 'settings.AUTH_USER_MODEL'.
wordle.Game.user: (fields.E301) Field defines a relation with the model 'auth.User', which has been swapped out.
	HINT: Update the relation to point at 'settings.AUTH_USER_MODEL'.

System check identified 3 issues (0 silenced).
C:\Users\james\Bootcamp\projects\project-75-emans-wordle\wordle_gato365\users\admin.py changed, reloading.
Watching for file changes with StatReloader
Performing system checks...

Exception in thread django-main-thread:
Traceback (most recent call last):
  File "C:\Python311\Lib\threading.py", line 1038, in _bootstrap_inner
    self.run()
  File "C:\Python311\Lib\threading.py", line 975, in run
    self._target(*self._args, **self._kwargs)
  File "C:\Users\james\AppData\Roaming\Python\Python311\site-packages\django\utils\autoreload.py", line 64, in wrapper
    fn(*args, **kwargs)
  File "C:\Users\james\AppData\Roaming\Python\Python311\site-packages\django\core\management\commands\runserver.py", line 133, in inner_run
    self.check(display_num_errors=True)
  File "C:\Users\james\AppData\Roaming\Python\Python311\site-packages\django\core\management\base.py", line 563, in check
    raise SystemCheckError(msg)
django.core.management.base.SystemCheckError: SystemCheckError: System check identified some issues:

ERRORS:
<class 'users.admin.ProfileInline'>: (admin.E202) 'users.Profile' has no ForeignKey to 'users.CustomUser'.
users.Profile.user: (fields.E301) Field defines a relation with the model 'auth.User', which has been swapped out.
	HINT: Update the relation to point at 'settings.AUTH_USER_MODEL'.
wordle.Game.user: (fields.E301) Field defines a relation with the model 'auth.User', which has been swapped out.
	HINT: Update the relation to point at 'settings.AUTH_USER_MODEL'.

System check identified 3 issues (0 silenced).
C:\Users\james\Bootcamp\projects\project-75-emans-wordle\wordle_gato365\users\models.py changed, reloading.
Watching for file changes with StatReloader
Exception in thread django-main-thread:
Traceback (most recent call last):
  File "C:\Python311\Lib\threading.py", line 1038, in _bootstrap_inner
    self.run()
  File "C:\Python311\Lib\threading.py", line 975, in run
    self._target(*self._args, **self._kwargs)
  File "C:\Users\james\AppData\Roaming\Python\Python311\site-packages\django\utils\autoreload.py", line 64, in wrapper
    fn(*args, **kwargs)
  File "C:\Users\james\AppData\Roaming\Python\Python311\site-packages\django\core\management\commands\runserver.py", line 125, in inner_run
    autoreload.raise_last_exception()
  File "C:\Users\james\AppData\Roaming\Python\Python311\site-packages\django\utils\autoreload.py", line 87, in raise_last_exception
    raise _exception[1]
  File "C:\Users\james\AppData\Roaming\Python\Python311\site-packages\django\core\management\__init__.py", line 394, in execute
    autoreload.check_errors(django.setup)()
  File "C:\Users\james\AppData\Roaming\Python\Python311\site-packages\django\utils\autoreload.py", line 64, in wrapper
    fn(*args, **kwargs)
  File "C:\Users\james\AppData\Roaming\Python\Python311\site-packages\django\__init__.py", line 24, in setup
    apps.populate(settings.INSTALLED_APPS)
  File "C:\Users\james\AppData\Roaming\Python\Python311\site-packages\django\apps\registry.py", line 116, in populate
    app_config.import_models()
  File "C:\Users\james\AppData\Roaming\Python\Python311\site-packages\django\apps\config.py", line 269, in import_models
    self.models_module = import_module(models_module_name)
                         ^^^^^^^^^^^^^^^^^^^^^^^^^^^^^^^^^
  File "C:\Python311\Lib\importlib\__init__.py", line 126, in import_module
    return _bootstrap._gcd_import(name[level:], package, level)
           ^^^^^^^^^^^^^^^^^^^^^^^^^^^^^^^^^^^^^^^^^^^^^^^^^^^^
  File "<frozen importlib._bootstrap>", line 1206, in _gcd_import
  File "<frozen importlib._bootstrap>", line 1178, in _find_and_load
  File "<frozen importlib._bootstrap>", line 1149, in _find_and_load_unlocked
  File "<frozen importlib._bootstrap>", line 690, in _load_unlocked
  File "<frozen importlib._bootstrap_external>", line 940, in exec_module
  File "<frozen importlib._bootstrap>", line 241, in _call_with_frames_removed
  File "C:\Users\james\Bootcamp\projects\project-75-emans-wordle\wordle_gato365\wordle\models.py", line 2, in <module>
    from users.models import User
  File "C:\Users\james\Bootcamp\projects\project-75-emans-wordle\wordle_gato365\users\models.py", line 8, in <module>
    class Profile(models.Model):
  File "C:\Users\james\Bootcamp\projects\project-75-emans-wordle\wordle_gato365\users\models.py", line 9, in Profile
    user = models.OneToOneField(settings.AUTH_USER_MODE, on_delete=models.CASCADE)
                                ^^^^^^^^
NameError: name 'settings' is not defined
C:\Users\james\Bootcamp\projects\project-75-emans-wordle\wordle_gato365\users\models.py changed, reloading.
Watching for file changes with StatReloader
Exception in thread django-main-thread:
Traceback (most recent call last):
  File "C:\Python311\Lib\threading.py", line 1038, in _bootstrap_inner
    self.run()
  File "C:\Python311\Lib\threading.py", line 975, in run
    self._target(*self._args, **self._kwargs)
  File "C:\Users\james\AppData\Roaming\Python\Python311\site-packages\django\utils\autoreload.py", line 64, in wrapper
    fn(*args, **kwargs)
  File "C:\Users\james\AppData\Roaming\Python\Python311\site-packages\django\core\management\commands\runserver.py", line 125, in inner_run
    autoreload.raise_last_exception()
  File "C:\Users\james\AppData\Roaming\Python\Python311\site-packages\django\utils\autoreload.py", line 87, in raise_last_exception
    raise _exception[1]
  File "C:\Users\james\AppData\Roaming\Python\Python311\site-packages\django\core\management\__init__.py", line 394, in execute
    autoreload.check_errors(django.setup)()
  File "C:\Users\james\AppData\Roaming\Python\Python311\site-packages\django\utils\autoreload.py", line 64, in wrapper
    fn(*args, **kwargs)
  File "C:\Users\james\AppData\Roaming\Python\Python311\site-packages\django\__init__.py", line 24, in setup
    apps.populate(settings.INSTALLED_APPS)
  File "C:\Users\james\AppData\Roaming\Python\Python311\site-packages\django\apps\registry.py", line 116, in populate
    app_config.import_models()
  File "C:\Users\james\AppData\Roaming\Python\Python311\site-packages\django\apps\config.py", line 269, in import_models
    self.models_module = import_module(models_module_name)
                         ^^^^^^^^^^^^^^^^^^^^^^^^^^^^^^^^^
  File "C:\Python311\Lib\importlib\__init__.py", line 126, in import_module
    return _bootstrap._gcd_import(name[level:], package, level)
           ^^^^^^^^^^^^^^^^^^^^^^^^^^^^^^^^^^^^^^^^^^^^^^^^^^^^
  File "<frozen importlib._bootstrap>", line 1206, in _gcd_import
  File "<frozen importlib._bootstrap>", line 1178, in _find_and_load
  File "<frozen importlib._bootstrap>", line 1149, in _find_and_load_unlocked
  File "<frozen importlib._bootstrap>", line 690, in _load_unlocked
  File "<frozen importlib._bootstrap_external>", line 940, in exec_module
  File "<frozen importlib._bootstrap>", line 241, in _call_with_frames_removed
  File "C:\Users\james\Bootcamp\projects\project-75-emans-wordle\wordle_gato365\wordle\models.py", line 2, in <module>
    from users.models import User
  File "C:\Users\james\Bootcamp\projects\project-75-emans-wordle\wordle_gato365\users\models.py", line 8, in <module>
    class Profile(models.Model):
  File "C:\Users\james\Bootcamp\projects\project-75-emans-wordle\wordle_gato365\users\models.py", line 9, in Profile
    user = models.OneToOneField(settings.AUTH_USER_MODEL, on_delete=models.CASCADE)
                                ^^^^^^^^
NameError: name 'settings' is not defined
C:\Users\james\Bootcamp\projects\project-75-emans-wordle\wordle_gato365\users\models.py changed, reloading.
Watching for file changes with StatReloader
Performing system checks...

Exception in thread django-main-thread:
Traceback (most recent call last):
  File "C:\Python311\Lib\threading.py", line 1038, in _bootstrap_inner
    self.run()
  File "C:\Python311\Lib\threading.py", line 975, in run
    self._target(*self._args, **self._kwargs)
  File "C:\Users\james\AppData\Roaming\Python\Python311\site-packages\django\utils\autoreload.py", line 64, in wrapper
    fn(*args, **kwargs)
  File "C:\Users\james\AppData\Roaming\Python\Python311\site-packages\django\core\management\commands\runserver.py", line 133, in inner_run
    self.check(display_num_errors=True)
  File "C:\Users\james\AppData\Roaming\Python\Python311\site-packages\django\core\management\base.py", line 563, in check
    raise SystemCheckError(msg)
django.core.management.base.SystemCheckError: SystemCheckError: System check identified some issues:

ERRORS:
wordle.Game.user: (fields.E301) Field defines a relation with the model 'auth.User', which has been swapped out.
	HINT: Update the relation to point at 'settings.AUTH_USER_MODEL'.

System check identified 1 issue (0 silenced).
C:\Users\james\Bootcamp\projects\project-75-emans-wordle\wordle_gato365\users\models.py changed, reloading.
Watching for file changes with StatReloader
Exception in thread django-main-thread:
Traceback (most recent call last):
  File "C:\Python311\Lib\threading.py", line 1038, in _bootstrap_inner
    self.run()
  File "C:\Python311\Lib\threading.py", line 975, in run
    self._target(*self._args, **self._kwargs)
  File "C:\Users\james\AppData\Roaming\Python\Python311\site-packages\django\utils\autoreload.py", line 64, in wrapper
    fn(*args, **kwargs)
  File "C:\Users\james\AppData\Roaming\Python\Python311\site-packages\django\core\management\commands\runserver.py", line 125, in inner_run
    autoreload.raise_last_exception()
  File "C:\Users\james\AppData\Roaming\Python\Python311\site-packages\django\utils\autoreload.py", line 87, in raise_last_exception
    raise _exception[1]
  File "C:\Users\james\AppData\Roaming\Python\Python311\site-packages\django\core\management\__init__.py", line 394, in execute
    autoreload.check_errors(django.setup)()
  File "C:\Users\james\AppData\Roaming\Python\Python311\site-packages\django\utils\autoreload.py", line 64, in wrapper
    fn(*args, **kwargs)
  File "C:\Users\james\AppData\Roaming\Python\Python311\site-packages\django\__init__.py", line 24, in setup
    apps.populate(settings.INSTALLED_APPS)
  File "C:\Users\james\AppData\Roaming\Python\Python311\site-packages\django\apps\registry.py", line 116, in populate
    app_config.import_models()
  File "C:\Users\james\AppData\Roaming\Python\Python311\site-packages\django\apps\config.py", line 269, in import_models
    self.models_module = import_module(models_module_name)
                         ^^^^^^^^^^^^^^^^^^^^^^^^^^^^^^^^^
  File "C:\Python311\Lib\importlib\__init__.py", line 126, in import_module
    return _bootstrap._gcd_import(name[level:], package, level)
           ^^^^^^^^^^^^^^^^^^^^^^^^^^^^^^^^^^^^^^^^^^^^^^^^^^^^
  File "<frozen importlib._bootstrap>", line 1206, in _gcd_import
  File "<frozen importlib._bootstrap>", line 1178, in _find_and_load
  File "<frozen importlib._bootstrap>", line 1149, in _find_and_load_unlocked
  File "<frozen importlib._bootstrap>", line 690, in _load_unlocked
  File "<frozen importlib._bootstrap_external>", line 940, in exec_module
  File "<frozen importlib._bootstrap>", line 241, in _call_with_frames_removed
  File "C:\Users\james\Bootcamp\projects\project-75-emans-wordle\wordle_gato365\wordle\models.py", line 2, in <module>
    from users.models import User
ImportError: cannot import name 'User' from 'users.models' (C:\Users\james\Bootcamp\projects\project-75-emans-wordle\wordle_gato365\users\models.py)
C:\Users\james\Bootcamp\projects\project-75-emans-wordle\wordle_gato365\wordle\models.py changed, reloading.
Watching for file changes with StatReloader
Exception in thread django-main-thread:
Traceback (most recent call last):
  File "C:\Python311\Lib\threading.py", line 1038, in _bootstrap_inner
    self.run()
  File "C:\Python311\Lib\threading.py", line 975, in run
    self._target(*self._args, **self._kwargs)
  File "C:\Users\james\AppData\Roaming\Python\Python311\site-packages\django\utils\autoreload.py", line 64, in wrapper
    fn(*args, **kwargs)
  File "C:\Users\james\AppData\Roaming\Python\Python311\site-packages\django\core\management\commands\runserver.py", line 125, in inner_run
    autoreload.raise_last_exception()
  File "C:\Users\james\AppData\Roaming\Python\Python311\site-packages\django\utils\autoreload.py", line 87, in raise_last_exception
    raise _exception[1]
  File "C:\Users\james\AppData\Roaming\Python\Python311\site-packages\django\core\management\__init__.py", line 394, in execute
    autoreload.check_errors(django.setup)()
  File "C:\Users\james\AppData\Roaming\Python\Python311\site-packages\django\utils\autoreload.py", line 64, in wrapper
    fn(*args, **kwargs)
  File "C:\Users\james\AppData\Roaming\Python\Python311\site-packages\django\__init__.py", line 24, in setup
    apps.populate(settings.INSTALLED_APPS)
  File "C:\Users\james\AppData\Roaming\Python\Python311\site-packages\django\apps\registry.py", line 116, in populate
    app_config.import_models()
  File "C:\Users\james\AppData\Roaming\Python\Python311\site-packages\django\apps\config.py", line 269, in import_models
    self.models_module = import_module(models_module_name)
                         ^^^^^^^^^^^^^^^^^^^^^^^^^^^^^^^^^
  File "C:\Python311\Lib\importlib\__init__.py", line 126, in import_module
    return _bootstrap._gcd_import(name[level:], package, level)
           ^^^^^^^^^^^^^^^^^^^^^^^^^^^^^^^^^^^^^^^^^^^^^^^^^^^^
  File "<frozen importlib._bootstrap>", line 1206, in _gcd_import
  File "<frozen importlib._bootstrap>", line 1178, in _find_and_load
  File "<frozen importlib._bootstrap>", line 1149, in _find_and_load_unlocked
  File "<frozen importlib._bootstrap>", line 690, in _load_unlocked
  File "<frozen importlib._bootstrap_external>", line 940, in exec_module
  File "<frozen importlib._bootstrap>", line 241, in _call_with_frames_removed
  File "C:\Users\james\Bootcamp\projects\project-75-emans-wordle\wordle_gato365\wordle\models.py", line 6, in <module>
    class Game(models.Model):
  File "C:\Users\james\Bootcamp\projects\project-75-emans-wordle\wordle_gato365\wordle\models.py", line 7, in Game
    user = models.ForeignKey(User, on_delete=models.CASCADE)
                             ^^^^
NameError: name 'User' is not defined
C:\Users\james\Bootcamp\projects\project-75-emans-wordle\wordle_gato365\wordle\models.py changed, reloading.
Watching for file changes with StatReloader
Performing system checks...

System check identified no issues (0 silenced).
September 16, 2024 - 16:05:11
Django version 5.0.6, using settings 'wordle_gato365.settings'
Starting development server at http://127.0.0.1:8000/
Quit the server with CTRL-BREAK.

C:\Users\james\Bootcamp\projects\project-75-emans-wordle\wordle_gato365\wordle_gato365\settings.py changed, reloading.
Watching for file changes with StatReloader
Performing system checks...

System check identified no issues (0 silenced).

You have 1 unapplied migration(s). Your project may not work properly until you apply the migrations for app(s): users.
Run 'python manage.py migrate' to apply them.
September 16, 2024 - 16:07:52
Django version 5.0.6, using settings 'wordle_gato365.settings'
Starting development server at http://127.0.0.1:8000/
Quit the server with CTRL-BREAK.

C:\Users\james\Bootcamp\projects\project-75-emans-wordle\wordle_gato365\wordle_gato365\settings.py changed, reloading.
Watching for file changes with StatReloader
Performing system checks...

System check identified no issues (0 silenced).

You have 1 unapplied migration(s). Your project may not work properly until you apply the migrations for app(s): users.
Run 'python manage.py migrate' to apply them.
September 16, 2024 - 16:07:55
Django version 5.0.6, using settings 'wordle_gato365.settings'
Starting development server at http://127.0.0.1:8000/
Quit the server with CTRL-BREAK.

C:\Users\james\Bootcamp\projects\project-75-emans-wordle\wordle_gato365\users\models.py changed, reloading.
Watching for file changes with StatReloader
Performing system checks...

System check identified no issues (0 silenced).

You have 1 unapplied migration(s). Your project may not work properly until you apply the migrations for app(s): users.
Run 'python manage.py migrate' to apply them.
September 16, 2024 - 16:11:30
Django version 5.0.6, using settings 'wordle_gato365.settings'
Starting development server at http://127.0.0.1:8000/
Quit the server with CTRL-BREAK.

C:\Users\james\Bootcamp\projects\project-75-emans-wordle\wordle_gato365\users\forms.py changed, reloading.
Watching for file changes with StatReloader
Performing system checks...

Exception in thread django-main-thread:
Traceback (most recent call last):
  File "C:\Python311\Lib\threading.py", line 1038, in _bootstrap_inner
    self.run()
  File "C:\Python311\Lib\threading.py", line 975, in run
    self._target(*self._args, **self._kwargs)
  File "C:\Users\james\AppData\Roaming\Python\Python311\site-packages\django\utils\autoreload.py", line 64, in wrapper
    fn(*args, **kwargs)
  File "C:\Users\james\AppData\Roaming\Python\Python311\site-packages\django\core\management\commands\runserver.py", line 133, in inner_run
    self.check(display_num_errors=True)
  File "C:\Users\james\AppData\Roaming\Python\Python311\site-packages\django\core\management\base.py", line 486, in check
    all_issues = checks.run_checks(
                 ^^^^^^^^^^^^^^^^^^
  File "C:\Users\james\AppData\Roaming\Python\Python311\site-packages\django\core\checks\registry.py", line 88, in run_checks
    new_errors = check(app_configs=app_configs, databases=databases)
                 ^^^^^^^^^^^^^^^^^^^^^^^^^^^^^^^^^^^^^^^^^^^^^^^^^^^
  File "C:\Users\james\AppData\Roaming\Python\Python311\site-packages\django\core\checks\urls.py", line 42, in check_url_namespaces_unique
    all_namespaces = _load_all_namespaces(resolver)
                     ^^^^^^^^^^^^^^^^^^^^^^^^^^^^^^
  File "C:\Users\james\AppData\Roaming\Python\Python311\site-packages\django\core\checks\urls.py", line 61, in _load_all_namespaces
    url_patterns = getattr(resolver, "url_patterns", [])
                   ^^^^^^^^^^^^^^^^^^^^^^^^^^^^^^^^^^^^^
  File "C:\Users\james\AppData\Roaming\Python\Python311\site-packages\django\utils\functional.py", line 47, in __get__
    res = instance.__dict__[self.name] = self.func(instance)
                                         ^^^^^^^^^^^^^^^^^^^
  File "C:\Users\james\AppData\Roaming\Python\Python311\site-packages\django\urls\resolvers.py", line 738, in url_patterns
    patterns = getattr(self.urlconf_module, "urlpatterns", self.urlconf_module)
                       ^^^^^^^^^^^^^^^^^^^
  File "C:\Users\james\AppData\Roaming\Python\Python311\site-packages\django\utils\functional.py", line 47, in __get__
    res = instance.__dict__[self.name] = self.func(instance)
                                         ^^^^^^^^^^^^^^^^^^^
  File "C:\Users\james\AppData\Roaming\Python\Python311\site-packages\django\urls\resolvers.py", line 731, in urlconf_module
    return import_module(self.urlconf_name)
           ^^^^^^^^^^^^^^^^^^^^^^^^^^^^^^^^
  File "C:\Python311\Lib\importlib\__init__.py", line 126, in import_module
    return _bootstrap._gcd_import(name[level:], package, level)
           ^^^^^^^^^^^^^^^^^^^^^^^^^^^^^^^^^^^^^^^^^^^^^^^^^^^^
  File "<frozen importlib._bootstrap>", line 1206, in _gcd_import
  File "<frozen importlib._bootstrap>", line 1178, in _find_and_load
  File "<frozen importlib._bootstrap>", line 1149, in _find_and_load_unlocked
  File "<frozen importlib._bootstrap>", line 690, in _load_unlocked
  File "<frozen importlib._bootstrap_external>", line 940, in exec_module
  File "<frozen importlib._bootstrap>", line 241, in _call_with_frames_removed
  File "C:\Users\james\Bootcamp\projects\project-75-emans-wordle\wordle_gato365\wordle_gato365\urls.py", line 19, in <module>
    from users import views as user_views
  File "C:\Users\james\Bootcamp\projects\project-75-emans-wordle\wordle_gato365\users\views.py", line 5, in <module>
    from .forms import UserRegisterForm, UserUpdateForm, ProfileUpdateForm
  File "C:\Users\james\Bootcamp\projects\project-75-emans-wordle\wordle_gato365\users\forms.py", line 6, in <module>
    CustomUser = get_user_model()
                 ^^^^^^^^^^^^^^
NameError: name 'get_user_model' is not defined
C:\Users\james\Bootcamp\projects\project-75-emans-wordle\wordle_gato365\users\forms.py changed, reloading.
Watching for file changes with StatReloader
Performing system checks...

System check identified no issues (0 silenced).

You have 1 unapplied migration(s). Your project may not work properly until you apply the migrations for app(s): users.
Run 'python manage.py migrate' to apply them.
September 16, 2024 - 16:12:29
Django version 5.0.6, using settings 'wordle_gato365.settings'
Starting development server at http://127.0.0.1:8000/
Quit the server with CTRL-BREAK.

C:\Users\james\Bootcamp\projects\project-75-emans-wordle\wordle_gato365\users\models.py changed, reloading.
Watching for file changes with StatReloader
Performing system checks...

System check identified no issues (0 silenced).

You have 2 unapplied migration(s). Your project may not work properly until you apply the migrations for app(s): users.
Run 'python manage.py migrate' to apply them.
September 16, 2024 - 16:14:18
Django version 5.0.6, using settings 'wordle_gato365.settings'
Starting development server at http://127.0.0.1:8000/
Quit the server with CTRL-BREAK.

C:\Users\james\Bootcamp\projects\project-75-emans-wordle\wordle_gato365\wordle_gato365\settings.py changed, reloading.
Watching for file changes with StatReloader
Performing system checks...

System check identified no issues (0 silenced).

You have 2 unapplied migration(s). Your project may not work properly until you apply the migrations for app(s): users.
Run 'python manage.py migrate' to apply them.
September 16, 2024 - 16:14:31
Django version 5.0.6, using settings 'wordle_gato365.settings'
Starting development server at http://127.0.0.1:8000/
Quit the server with CTRL-BREAK.

C:\Users\james\Bootcamp\projects\project-75-emans-wordle\wordle_gato365\wordle_gato365\settings.py changed, reloading.
Watching for file changes with StatReloader
Exception in thread django-main-thread:
Traceback (most recent call last):
  File "C:\Python311\Lib\threading.py", line 1038, in _bootstrap_inner
    self.run()
  File "C:\Python311\Lib\threading.py", line 975, in run
    self._target(*self._args, **self._kwargs)
  File "C:\Users\james\AppData\Roaming\Python\Python311\site-packages\django\utils\autoreload.py", line 64, in wrapper
    fn(*args, **kwargs)
  File "C:\Users\james\AppData\Roaming\Python\Python311\site-packages\django\core\management\commands\runserver.py", line 125, in inner_run
    autoreload.raise_last_exception()
  File "C:\Users\james\AppData\Roaming\Python\Python311\site-packages\django\utils\autoreload.py", line 87, in raise_last_exception
    raise _exception[1]
  File "C:\Users\james\AppData\Roaming\Python\Python311\site-packages\django\core\management\__init__.py", line 394, in execute
    autoreload.check_errors(django.setup)()
  File "C:\Users\james\AppData\Roaming\Python\Python311\site-packages\django\utils\autoreload.py", line 64, in wrapper
    fn(*args, **kwargs)
  File "C:\Users\james\AppData\Roaming\Python\Python311\site-packages\django\__init__.py", line 24, in setup
    apps.populate(settings.INSTALLED_APPS)
  File "C:\Users\james\AppData\Roaming\Python\Python311\site-packages\django\apps\registry.py", line 91, in populate
    app_config = AppConfig.create(entry)
                 ^^^^^^^^^^^^^^^^^^^^^^^
  File "C:\Users\james\AppData\Roaming\Python\Python311\site-packages\django\apps\config.py", line 193, in create
    import_module(entry)
  File "C:\Python311\Lib\importlib\__init__.py", line 126, in import_module
    return _bootstrap._gcd_import(name[level:], package, level)
           ^^^^^^^^^^^^^^^^^^^^^^^^^^^^^^^^^^^^^^^^^^^^^^^^^^^^
  File "<frozen importlib._bootstrap>", line 1206, in _gcd_import
  File "<frozen importlib._bootstrap>", line 1178, in _find_and_load
  File "<frozen importlib._bootstrap>", line 1128, in _find_and_load_unlocked
  File "<frozen importlib._bootstrap>", line 241, in _call_with_frames_removed
  File "<frozen importlib._bootstrap>", line 1206, in _gcd_import
  File "<frozen importlib._bootstrap>", line 1178, in _find_and_load
  File "<frozen importlib._bootstrap>", line 1128, in _find_and_load_unlocked
  File "<frozen importlib._bootstrap>", line 241, in _call_with_frames_removed
  File "<frozen importlib._bootstrap>", line 1206, in _gcd_import
  File "<frozen importlib._bootstrap>", line 1178, in _find_and_load
  File "<frozen importlib._bootstrap>", line 1142, in _find_and_load_unlocked
ModuleNotFoundError: No module named 'usersdjango'
C:\Users\james\Bootcamp\projects\project-75-emans-wordle\wordle_gato365\wordle_gato365\settings.py changed, reloading.
Watching for file changes with StatReloader
Exception in thread django-main-thread:
Traceback (most recent call last):
  File "C:\Python311\Lib\threading.py", line 1038, in _bootstrap_inner
    self.run()
  File "C:\Python311\Lib\threading.py", line 975, in run
    self._target(*self._args, **self._kwargs)
  File "C:\Users\james\AppData\Roaming\Python\Python311\site-packages\django\utils\autoreload.py", line 64, in wrapper
    fn(*args, **kwargs)
  File "C:\Users\james\AppData\Roaming\Python\Python311\site-packages\django\core\management\commands\runserver.py", line 125, in inner_run
    autoreload.raise_last_exception()
  File "C:\Users\james\AppData\Roaming\Python\Python311\site-packages\django\utils\autoreload.py", line 87, in raise_last_exception
    raise _exception[1]
  File "C:\Users\james\AppData\Roaming\Python\Python311\site-packages\django\core\management\__init__.py", line 394, in execute
    autoreload.check_errors(django.setup)()
  File "C:\Users\james\AppData\Roaming\Python\Python311\site-packages\django\utils\autoreload.py", line 64, in wrapper
    fn(*args, **kwargs)
  File "C:\Users\james\AppData\Roaming\Python\Python311\site-packages\django\__init__.py", line 24, in setup
    apps.populate(settings.INSTALLED_APPS)
  File "C:\Users\james\AppData\Roaming\Python\Python311\site-packages\django\apps\registry.py", line 93, in populate
    raise ImproperlyConfigured(
django.core.exceptions.ImproperlyConfigured: Application labels aren't unique, duplicates: users
C:\Users\james\Bootcamp\projects\project-75-emans-wordle\wordle_gato365\wordle_gato365\settings.py changed, reloading.
Watching for file changes with StatReloader
Performing system checks...

System check identified no issues (0 silenced).

You have 2 unapplied migration(s). Your project may not work properly until you apply the migrations for app(s): users.
Run 'python manage.py migrate' to apply them.
September 16, 2024 - 16:15:15
Django version 5.0.6, using settings 'wordle_gato365.settings'
Starting development server at http://127.0.0.1:8000/
Quit the server with CTRL-BREAK.

C:\Users\james\Bootcamp\projects\project-75-emans-wordle\wordle_gato365\wordle_gato365\settings.py changed, reloading.
Watching for file changes with StatReloader
Exception in thread django-main-thread:
Traceback (most recent call last):
  File "C:\Users\james\AppData\Roaming\Python\Python311\site-packages\django\apps\registry.py", line 158, in get_app_config
    return self.app_configs[app_label]
           ~~~~~~~~~~~~~~~~^^^^^^^^^^^
KeyError: 'users'

During handling of the above exception, another exception occurred:

Traceback (most recent call last):
  File "C:\Users\james\AppData\Roaming\Python\Python311\site-packages\django\contrib\auth\__init__.py", line 188, in get_user_model
    return django_apps.get_model(settings.AUTH_USER_MODEL, require_ready=False)
           ^^^^^^^^^^^^^^^^^^^^^^^^^^^^^^^^^^^^^^^^^^^^^^^^^^^^^^^^^^^^^^^^^^^^
  File "C:\Users\james\AppData\Roaming\Python\Python311\site-packages\django\apps\registry.py", line 208, in get_model
    app_config = self.get_app_config(app_label)
                 ^^^^^^^^^^^^^^^^^^^^^^^^^^^^^^
  File "C:\Users\james\AppData\Roaming\Python\Python311\site-packages\django\apps\registry.py", line 165, in get_app_config
    raise LookupError(message)
LookupError: No installed app with label 'users'.

During handling of the above exception, another exception occurred:

Traceback (most recent call last):
  File "C:\Python311\Lib\threading.py", line 1038, in _bootstrap_inner
    self.run()
  File "C:\Python311\Lib\threading.py", line 975, in run
    self._target(*self._args, **self._kwargs)
  File "C:\Users\james\AppData\Roaming\Python\Python311\site-packages\django\utils\autoreload.py", line 64, in wrapper
    fn(*args, **kwargs)
  File "C:\Users\james\AppData\Roaming\Python\Python311\site-packages\django\core\management\commands\runserver.py", line 125, in inner_run
    autoreload.raise_last_exception()
  File "C:\Users\james\AppData\Roaming\Python\Python311\site-packages\django\utils\autoreload.py", line 87, in raise_last_exception
    raise _exception[1]
  File "C:\Users\james\AppData\Roaming\Python\Python311\site-packages\django\core\management\__init__.py", line 394, in execute
    autoreload.check_errors(django.setup)()
  File "C:\Users\james\AppData\Roaming\Python\Python311\site-packages\django\utils\autoreload.py", line 64, in wrapper
    fn(*args, **kwargs)
  File "C:\Users\james\AppData\Roaming\Python\Python311\site-packages\django\__init__.py", line 24, in setup
    apps.populate(settings.INSTALLED_APPS)
  File "C:\Users\james\AppData\Roaming\Python\Python311\site-packages\django\apps\registry.py", line 124, in populate
    app_config.ready()
  File "C:\Users\james\AppData\Roaming\Python\Python311\site-packages\django\contrib\admin\apps.py", line 27, in ready
    self.module.autodiscover()
  File "C:\Users\james\AppData\Roaming\Python\Python311\site-packages\django\contrib\admin\__init__.py", line 52, in autodiscover
    autodiscover_modules("admin", register_to=site)
  File "C:\Users\james\AppData\Roaming\Python\Python311\site-packages\django\utils\module_loading.py", line 58, in autodiscover_modules
    import_module("%s.%s" % (app_config.name, module_to_search))
  File "C:\Python311\Lib\importlib\__init__.py", line 126, in import_module
    return _bootstrap._gcd_import(name[level:], package, level)
           ^^^^^^^^^^^^^^^^^^^^^^^^^^^^^^^^^^^^^^^^^^^^^^^^^^^^
  File "<frozen importlib._bootstrap>", line 1206, in _gcd_import
  File "<frozen importlib._bootstrap>", line 1178, in _find_and_load
  File "<frozen importlib._bootstrap>", line 1149, in _find_and_load_unlocked
  File "<frozen importlib._bootstrap>", line 690, in _load_unlocked
  File "<frozen importlib._bootstrap_external>", line 940, in exec_module
  File "<frozen importlib._bootstrap>", line 241, in _call_with_frames_removed
  File "C:\Users\james\AppData\Roaming\Python\Python311\site-packages\django\contrib\auth\admin.py", line 6, in <module>
    from django.contrib.auth.forms import (
  File "C:\Users\james\AppData\Roaming\Python\Python311\site-packages\django\contrib\auth\forms.py", line 18, in <module>
    UserModel = get_user_model()
                ^^^^^^^^^^^^^^^^
  File "C:\Users\james\AppData\Roaming\Python\Python311\site-packages\django\contrib\auth\__init__.py", line 194, in get_user_model
    raise ImproperlyConfigured(
django.core.exceptions.ImproperlyConfigured: AUTH_USER_MODEL refers to model 'users.CustomUser' that has not been installed
C:\Users\james\Bootcamp\projects\project-75-emans-wordle\wordle_gato365\wordle_gato365\settings.py changed, reloading.
Watching for file changes with StatReloader
Performing system checks...

System check identified no issues (0 silenced).

You have 2 unapplied migration(s). Your project may not work properly until you apply the migrations for app(s): users.
Run 'python manage.py migrate' to apply them.
September 17, 2024 - 03:33:19
Django version 5.0.6, using settings 'wordle_gato365.settings'
Starting development server at http://127.0.0.1:8000/
Quit the server with CTRL-BREAK.

