Watching for file changes with StatReloader
Performing system checks...

System check identified no issues (0 silenced).
September 21, 2024 - 20:31:38
Django version 5.0.6, using settings 'wordle_gato365.settings'
Starting development server at http://127.0.0.1:8000/
Quit the server with CTRL-BREAK.

C:\Users\james\Bootcamp\projects\project-75-emans-wordle\wordle_gato365\wordle_gato365\settings.py changed, reloading.
Watching for file changes with StatReloader
Performing system checks...

System check identified no issues (0 silenced).
September 21, 2024 - 20:39:29
Django version 5.0.6, using settings 'wordle_gato365.settings'
Starting development server at http://127.0.0.1:8000/
Quit the server with CTRL-BREAK.

C:\Users\james\Bootcamp\projects\project-75-emans-wordle\wordle_gato365\wordle\models.py changed, reloading.
Watching for file changes with StatReloader
Performing system checks...

System check identified no issues (0 silenced).
September 21, 2024 - 20:40:50
Django version 5.0.6, using settings 'wordle_gato365.settings'
Starting development server at http://127.0.0.1:8000/
Quit the server with CTRL-BREAK.

C:\Users\james\Bootcamp\projects\project-75-emans-wordle\wordle_gato365\wordle\models.py changed, reloading.
Watching for file changes with StatReloader
Exception in thread django-main-thread:
Traceback (most recent call last):
  File "C:\Python311\Lib\threading.py", line 1038, in _bootstrap_inner
    self.run()
  File "C:\Python311\Lib\threading.py", line 975, in run
    self._target(*self._args, **self._kwargs)
  File "C:\Users\james\AppData\Roaming\Python\Python311\site-packages\django\utils\autoreload.py", line 64, in wrapper
    fn(*args, **kwargs)
  File "C:\Users\james\AppData\Roaming\Python\Python311\site-packages\django\core\management\commands\runserver.py", line 125, in inner_run
    autoreload.raise_last_exception()
  File "C:\Users\james\AppData\Roaming\Python\Python311\site-packages\django\utils\autoreload.py", line 87, in raise_last_exception
    raise _exception[1]
  File "C:\Users\james\AppData\Roaming\Python\Python311\site-packages\django\core\management\__init__.py", line 394, in execute
    autoreload.check_errors(django.setup)()
  File "C:\Users\james\AppData\Roaming\Python\Python311\site-packages\django\utils\autoreload.py", line 64, in wrapper
    fn(*args, **kwargs)
  File "C:\Users\james\AppData\Roaming\Python\Python311\site-packages\django\__init__.py", line 24, in setup
    apps.populate(settings.INSTALLED_APPS)
  File "C:\Users\james\AppData\Roaming\Python\Python311\site-packages\django\apps\registry.py", line 116, in populate
    app_config.import_models()
  File "C:\Users\james\AppData\Roaming\Python\Python311\site-packages\django\apps\config.py", line 269, in import_models
    self.models_module = import_module(models_module_name)
                         ^^^^^^^^^^^^^^^^^^^^^^^^^^^^^^^^^
  File "C:\Python311\Lib\importlib\__init__.py", line 126, in import_module
    return _bootstrap._gcd_import(name[level:], package, level)
           ^^^^^^^^^^^^^^^^^^^^^^^^^^^^^^^^^^^^^^^^^^^^^^^^^^^^
  File "<frozen importlib._bootstrap>", line 1206, in _gcd_import
  File "<frozen importlib._bootstrap>", line 1178, in _find_and_load
  File "<frozen importlib._bootstrap>", line 1149, in _find_and_load_unlocked
  File "<frozen importlib._bootstrap>", line 690, in _load_unlocked
  File "<frozen importlib._bootstrap_external>", line 936, in exec_module
  File "<frozen importlib._bootstrap_external>", line 1074, in get_code
  File "<frozen importlib._bootstrap_external>", line 1004, in source_to_code
  File "<frozen importlib._bootstrap>", line 241, in _call_with_frames_removed
  File "C:\Users\james\Bootcamp\projects\project-75-emans-wordle\wordle_gato365\wordle\models.py", line 6
    User = get_user_model()c
                           ^
SyntaxError: invalid syntax
C:\Users\james\Bootcamp\projects\project-75-emans-wordle\wordle_gato365\wordle\models.py changed, reloading.
Watching for file changes with StatReloader
Exception in thread django-main-thread:
Traceback (most recent call last):
  File "C:\Python311\Lib\threading.py", line 1038, in _bootstrap_inner
    self.run()
  File "C:\Python311\Lib\threading.py", line 975, in run
    self._target(*self._args, **self._kwargs)
  File "C:\Users\james\AppData\Roaming\Python\Python311\site-packages\django\utils\autoreload.py", line 64, in wrapper
    fn(*args, **kwargs)
  File "C:\Users\james\AppData\Roaming\Python\Python311\site-packages\django\core\management\commands\runserver.py", line 125, in inner_run
    autoreload.raise_last_exception()
  File "C:\Users\james\AppData\Roaming\Python\Python311\site-packages\django\utils\autoreload.py", line 87, in raise_last_exception
    raise _exception[1]
  File "C:\Users\james\AppData\Roaming\Python\Python311\site-packages\django\core\management\__init__.py", line 394, in execute
    autoreload.check_errors(django.setup)()
  File "C:\Users\james\AppData\Roaming\Python\Python311\site-packages\django\utils\autoreload.py", line 64, in wrapper
    fn(*args, **kwargs)
  File "C:\Users\james\AppData\Roaming\Python\Python311\site-packages\django\__init__.py", line 24, in setup
    apps.populate(settings.INSTALLED_APPS)
  File "C:\Users\james\AppData\Roaming\Python\Python311\site-packages\django\apps\registry.py", line 116, in populate
    app_config.import_models()
  File "C:\Users\james\AppData\Roaming\Python\Python311\site-packages\django\apps\config.py", line 269, in import_models
    self.models_module = import_module(models_module_name)
                         ^^^^^^^^^^^^^^^^^^^^^^^^^^^^^^^^^
  File "C:\Python311\Lib\importlib\__init__.py", line 126, in import_module
    return _bootstrap._gcd_import(name[level:], package, level)
           ^^^^^^^^^^^^^^^^^^^^^^^^^^^^^^^^^^^^^^^^^^^^^^^^^^^^
  File "<frozen importlib._bootstrap>", line 1206, in _gcd_import
  File "<frozen importlib._bootstrap>", line 1178, in _find_and_load
  File "<frozen importlib._bootstrap>", line 1149, in _find_and_load_unlocked
  File "<frozen importlib._bootstrap>", line 690, in _load_unlocked
  File "<frozen importlib._bootstrap_external>", line 936, in exec_module
  File "<frozen importlib._bootstrap_external>", line 1074, in get_code
  File "<frozen importlib._bootstrap_external>", line 1004, in source_to_code
  File "<frozen importlib._bootstrap>", line 241, in _call_with_frames_removed
  File "C:\Users\james\Bootcamp\projects\project-75-emans-wordle\wordle_gato365\wordle\models.py", line 19
    User = get_user_model()c
                           ^
SyntaxError: invalid syntax
C:\Users\james\Bootcamp\projects\project-75-emans-wordle\wordle_gato365\wordle\models.py changed, reloading.
Watching for file changes with StatReloader
Exception in thread django-main-thread:
Traceback (most recent call last):
  File "C:\Python311\Lib\threading.py", line 1038, in _bootstrap_inner
    self.run()
  File "C:\Python311\Lib\threading.py", line 975, in run
    self._target(*self._args, **self._kwargs)
  File "C:\Users\james\AppData\Roaming\Python\Python311\site-packages\django\utils\autoreload.py", line 64, in wrapper
    fn(*args, **kwargs)
  File "C:\Users\james\AppData\Roaming\Python\Python311\site-packages\django\core\management\commands\runserver.py", line 125, in inner_run
    autoreload.raise_last_exception()
  File "C:\Users\james\AppData\Roaming\Python\Python311\site-packages\django\utils\autoreload.py", line 87, in raise_last_exception
    raise _exception[1]
  File "C:\Users\james\AppData\Roaming\Python\Python311\site-packages\django\core\management\__init__.py", line 394, in execute
    autoreload.check_errors(django.setup)()
  File "C:\Users\james\AppData\Roaming\Python\Python311\site-packages\django\utils\autoreload.py", line 64, in wrapper
    fn(*args, **kwargs)
  File "C:\Users\james\AppData\Roaming\Python\Python311\site-packages\django\__init__.py", line 24, in setup
    apps.populate(settings.INSTALLED_APPS)
  File "C:\Users\james\AppData\Roaming\Python\Python311\site-packages\django\apps\registry.py", line 116, in populate
    app_config.import_models()
  File "C:\Users\james\AppData\Roaming\Python\Python311\site-packages\django\apps\config.py", line 269, in import_models
    self.models_module = import_module(models_module_name)
                         ^^^^^^^^^^^^^^^^^^^^^^^^^^^^^^^^^
  File "C:\Python311\Lib\importlib\__init__.py", line 126, in import_module
    return _bootstrap._gcd_import(name[level:], package, level)
           ^^^^^^^^^^^^^^^^^^^^^^^^^^^^^^^^^^^^^^^^^^^^^^^^^^^^
  File "<frozen importlib._bootstrap>", line 1206, in _gcd_import
  File "<frozen importlib._bootstrap>", line 1178, in _find_and_load
  File "<frozen importlib._bootstrap>", line 1149, Watching for file changes with StatReloader
Exception in thread django-main-thread:
Traceback (most recent call last):
  File "C:\Python311\Lib\threading.py", line 1038, in _bootstrap_inner
    self.run()
  File "C:\Python311\Lib\threading.py", line 975, in run
    self._target(*self._args, **self._kwargs)
  File "C:\Users\james\AppData\Roaming\Python\Python311\site-packages\django\utils\autoreload.py", line 64, in wrapper
    fn(*args, **kwargs)
  File "C:\Users\james\AppData\Roaming\Python\Python311\site-packages\django\core\management\commands\runserver.py", line 125, in inner_runC:\Users\james\Bootcamp\projects\project-75-emans-wordle\wordle_gato365\wordle\models.py changed, reloading.
Watching for file changes with StatReloader
Performing system checks...

System check identified no issues (0 silenced).
September 21, 2024 - 20:41:09
Django version 5.0.6, using settings 'wordle_gato365.settings'
Starting development server at http://127.0.0.1:8000/
Quit the server with CTRL-BREAK.

C:\Users\james\Bootcamp\projects\project-75-emans-wordle\wordle_gato365\wordle\models.py changed, reloading.
Watching for file changes with StatReloader
Performing system checks...

System check identified no issues (0 silenced).
September 21, 2024 - 20:41:17
Django version 5.0.6, using settings 'wordle_gato365.settings'
Starting development server at http://127.0.0.1:8000/
Quit the server with CTRL-BREAK.

C:\Users\james\Bootcamp\projects\project-75-emans-wordle\wordle_gato365\wordle\models.py changed, reloading.
Watching for file changes with StatReloader
Performing system checks...

System check identified no issues (0 silenced).
September 21, 2024 - 20:41:54
Django version 5.0.6, using settings 'wordle_gato365.settings'
Starting development server at http://127.0.0.1:8000/
Quit the server with CTRL-BREAK.

C:\Users\james\Bootcamp\projects\project-75-emans-wordle\wordle_gato365\wordle\models.py changed, reloading.
Watching for file changes with StatReloader
Performing system checks...

System check identified no issues (0 silenced).
September 21, 2024 - 20:41:59
Django version 5.0.6, using settings 'wordle_gato365.settings'
Starting development server at http://127.0.0.1:8000/
Quit the server with CTRL-BREAK.

C:\Users\james\Bootcamp\projects\project-75-emans-wordle\wordle_gato365\wordle\models.py changed, reloading.
Watching for file changes with StatReloader
Performing system checks...

System check identified no issues (0 silenced).
September 21, 2024 - 20:42:04
Django version 5.0.6, using settings 'wordle_gato365.settings'
Starting development server at http://127.0.0.1:8000/
Quit the server with CTRL-BREAK.

C:\Users\james\Bootcamp\projects\project-75-emans-wordle\wordle_gato365\wordle\models.py changed, reloading.
Watching for file changes with StatReloader
Performing system checks...

System check identified no issues (0 silenced).
September 21, 2024 - 20:42:08
Django version 5.0.6, using settings 'wordle_gato365.settings'
Starting development server at http://127.0.0.1:8000/
Quit the server with CTRL-BREAK.

C:\Users\james\Bootcamp\projects\project-75-emans-wordle\wordle_gato365\wordle\views.py changed, reloading.
Watching for file changes with StatReloader
Performing system checks...

System check identified no issues (0 silenced).
September 21, 2024 - 20:44:50
Django version 5.0.6, using settings 'wordle_gato365.settings'
Starting development server at http://127.0.0.1:8000/
Quit the server with CTRL-BREAK.

C:\Users\james\Bootcamp\projects\project-75-emans-wordle\wordle_gato365\wordle\views.py changed, reloading.
Watching for file changes with StatReloader
Performing system checks...

System check identified no issues (0 silenced).
September 21, 2024 - 20:45:08
Django version 5.0.6, using settings 'wordle_gato365.settings'
Starting development server at http://127.0.0.1:8000/
Quit the server with CTRL-BREAK.

"POST /logout/ HTTP/1.1" 302 0
"GET /login/ HTTP/1.1" 200 3696
STREAM b'IHDR' 16 13
STREAM b'eXIf' 41 68
STREAM b'IDAT' 121 65536
STREAM b'IHDR' 16 13
STREAM b'eXIf' 41 68
STREAM b'IDAT' 121 65536
"POST /login/ HTTP/1.1" 302 0
"GET /game-history/ HTTP/1.1" 200 11921
"GET /game/ HTTP/1.1" 200 3624
Internal Server Error: /game/
Traceback (most recent call last):
  File "C:\Users\james\AppData\Roaming\Python\Python311\site-packages\django\core\handlers\exception.py", line 55, in inner
    response = get_response(request)
               ^^^^^^^^^^^^^^^^^^^^^
  File "C:\Users\james\AppData\Roaming\Python\Python311\site-packages\django\core\handlers\base.py", line 197, in _get_response
    response = wrapped_callback(request, *callback_args, **callback_kwargs)
               ^^^^^^^^^^^^^^^^^^^^^^^^^^^^^^^^^^^^^^^^^^^^^^^^^^^^^^^^^^^^
  File "C:\Users\james\AppData\Roaming\Python\Python311\site-packages\django\contrib\auth\decorators.py", line 23, in _wrapper_view
    return view_func(request, *args, **kwargs)
           ^^^^^^^^^^^^^^^^^^^^^^^^^^^^^^^^^^^
  File "C:\Users\james\AppData\Roaming\Python\Python311\site-packages\django\utils\decorators.py", line 188, in _view_wrapper
    result = _process_exception(request, e)
             ^^^^^^^^^^^^^^^^^^^^^^^^^^^^^^
  File "C:\Users\james\AppData\Roaming\Python\Python311\site-packages\django\utils\decorators.py", line 186, in _view_wrapper
    response = view_func(request, *args, **kwargs)
               ^^^^^^^^^^^^^^^^^^^^^^^^^^^^^^^^^^^
  File "C:\Users\james\AppData\Roaming\Python\Python311\site-packages\django\views\decorators\http.py", line 64, in inner
    return func(request, *args, **kwargs)
           ^^^^^^^^^^^^^^^^^^^^^^^^^^^^^^
  File "C:\Users\james\Bootcamp\projects\project-75-emans-wordle\wordle_gato365\wordle\views.py", line 42, in game_view
    ret
NameError: name 'ret' is not defined
"POST /game/ HTTP/1.1" 500 101697
C:\Users\james\Bootcamp\projects\project-75-emans-wordle\wordle_gato365\wordle\views.py changed, reloading.
Watching for file changes with StatReloader
Performing system checks...

System check identified no issues (0 silenced).
September 21, 2024 - 20:47:00
Django version 5.0.6, using settings 'wordle_gato365.settings'
Starting development server at http://127.0.0.1:8000/
Quit the server with CTRL-BREAK.

gato365.settings'
Starting development server at http://127.0.0.1:8000/
Quit the server with CTRL-BREAK.

Today's date: 2024-09-22
Today's word: tasty - 2024-09-21
Created game: Game object (24)
"POST /game/ HTTP/1.1" 200 35
Game 24: Correct word is tasty, guess is buddy
"POST /submit_guess/ HTTP/1.1" 200 279
Game 24: Correct word is tasty, guess is hasty
"POST /submit_guess/ HTTP/1.1" 200 282
Game 24: Correct word is tasty, guess is tasty
"POST /submit_guess/ HTTP/1.1" 200 284
"POST /update_game_time/ HTTP/1.1" 200 21
"POST /update_guess_times/ HTTP/1.1" 200 21
